Workbook
Name Elenco_Misure: 'Tab-Mis'!$B$5:$B$184
Name Misure_Campionate: 'Tab-Mis'!$B$5:$P$184
Name MisureRumore: 'Tab-Mis'!#REF!
Name NumeroRumore: 'Tab-Mis'!#REF!
Name TdiR: 'Tab-Mis'!$L$20:$L$24
Name Elenco_Misure: #REF!
Name Misure_Campionate: #REF!
Name _ftn1: 'Tab-Mis (3)'!#REF!
Name _ftn2: 'Tab-Mis (3)'!#REF!
Name _ftn3: 'Tab-Mis (3)'!#REF!
Name _ftn4: 'Tab-Mis (3)'!#REF!
Name _ftn5: 'Tab-Mis (3)'!#REF!
Name _ftnref1: 'Tab-Mis (3)'!#REF!
Name _ftnref2: 'Tab-Mis (3)'!#REF!
Name _ftnref3: 'Tab-Mis (3)'!#REF!
Name _ftnref4: 'Tab-Mis (3)'!#REF!
Name _ftnref5: 'Tab-Mis (3)'!#REF!
Name Elenco_Misure: 'Tab-Mis (3)'!$B$5:$B$184
Name Misure_Campionate: 'Tab-Mis (3)'!$B$5:$P$184
Name MisureRumore: 'Tab-Mis (3)'!#REF!
Name NumeroRumore: 'Tab-Mis (3)'!#REF!
Name TdiR: 'Tab-Mis (3)'!$L$20:$L$24
Name _ftn1: 'Tab-Mis'!#REF!
Name _ftn2: 'Tab-Mis'!#REF!
Name _ftn3: 'Tab-Mis'!#REF!
Name _ftn4: 'Tab-Mis'!#REF!
Name _ftn5: 'Tab-Mis'!#REF!
Name _ftnref1: 'Tab-Mis'!#REF!
Name _ftnref2: 'Tab-Mis'!#REF!
Name _ftnref3: 'Tab-Mis'!#REF!
Name _ftnref4: 'Tab-Mis'!#REF!
Name _ftnref5: 'Tab-Mis'!#REF!

Sheet Riepilogo
A4: Gruppi Omogenei di Esposizione | B4: Scheda Gruppo omogeneo | C4: Parametro di riferimento | D4: ='Scheda 1'!H44 | E4: Incertezza complessiva U (LEX,8h) | F4: LEX MAX | G4: Massimo dei PPEAK misurati | H4: LEX,8h con attenuazione D.P.I. uditivo (**) | I4: PPEAK con attenuazione D.P.I. uditivo | J4: CLASSE DI RISCHIO BASSA | K4: CLASSE DI RISCHIO MEDIA | L4: CLASSE DI RISCHIO ALTA | M4: Esposizone a vibrazioni (*) | N4: Esposizone a ototossici | O4: Rumori impulsisi possibili
A5: ='Scheda 1'!F8 | B5: 1 | C5: ='Scheda 1'!H44 | D5: ='Scheda 1'!I44 | E5: ='Scheda 1'!K44 | F5: ='Scheda 1'!O44 | G5: ='Scheda 1'!O45 | H5: =IF(F5>87,'Scheda 1'!AM$11,"non previsto") | I5: =IF(G5>140,'Scheda 1'!T$41,"non previsto") | J5: =IF(F5<80,"BASSA"," ") | K5: =IF(F5>85," ",IF(F5>80,"MEDIA",IF(F5<80," ",IF(F5<87," "," ")))) | L5: =IF(F5>85,"ALTA"," ") | M5: WBV | N5: SI | O5: NO
A6: ='Scheda 2'!F8 | B6: 2 | C6: ='Scheda 2'!H44 | D6: ='Scheda 2'!I44 | E6: ='Scheda 2'!K44 | F6: ='Scheda 2'!O44 | G6: ='Scheda 2'!O45 | H6: =IF(F6>87,'Scheda 2'!AM$11,"non previsto") | I6: =IF(G6>140,'Scheda 2'!T$41,"non previsto") | J6: =IF(F6<80,"BASSA"," ") | K6: =IF(F6>85," ",IF(F6>80,"MEDIA",IF(F6<80," ",IF(F6<87," "," ")))) | L6: =IF(F6>85,"ALTA"," ") | M6: HAV | N6: SI | O6: NO
A7: ='Scheda 3'!F8 | B7: 3 | C7: ='Scheda 3'!H44 | D7: ='Scheda 3'!I44 | E7: ='Scheda 3'!K44 | F7: ='Scheda 3'!O44 | G7: ='Scheda 3'!O45 | H7: =IF(F7>87,'Scheda 3'!AM$11,"non previsto") | I7: =IF(G7>140,'Scheda 3'!T$41,"non previsto") | J7: =IF(F7<80,"BASSA"," ") | K7: =IF(F7>85," ",IF(F7>80,"MEDIA",IF(F7<80," ",IF(F7<87," "," ")))) | L7: =IF(F7>85,"ALTA"," ") | M7: HAV | N7: SI | O7: NO
A8: ='Scheda 4'!F8 | B8: 4 | C8: ='Scheda 4'!H44 | D8: ='Scheda 4'!I44 | E8: ='Scheda 4'!K44 | F8: ='Scheda 4'!O44 | G8: ='Scheda 4'!O45 | H8: =IF(F8>84,'Scheda 4'!AM$11,"non previsto") | I8: =IF(G8>140,'Scheda 4'!T$41,"non previsto") | J8: =IF(F8<80,"BASSA"," ") | K8: =IF(F8>85," ",IF(F8>80,"MEDIA",IF(F8<80," ",IF(F8<87," "," ")))) | L8: =IF(F8>85,"ALTA"," ") | M8: HAV | N8: NO | O8: NO
A9: ='Scheda 5'!F8 | B9: 5 | C9: ='Scheda 5'!H44 | D9: ='Scheda 5'!I44 | E9: ='Scheda 5'!K44 | F9: ='Scheda 5'!O44 | G9: ='Scheda 5'!O45 | H9: =IF(F9>87,'Scheda 5'!AM$11,"non previsto") | I9: =IF(G9>540,'Scheda 5'!T$45,"non previsto") | J9: =IF(F9<80,"BASSA"," ") | K9: =IF(F9>85," ",IF(F9>80,"MEDIA",IF(F9<80," ",IF(F9<87," "," ")))) | L9: =IF(F9>85,"ALTA"," ") | M9: HAV | N9: NO | O9: NO
A10: ='Scheda 6'!F8 | B10: 6 | C10: ='Scheda 6'!H44 | D10: ='Scheda 6'!I44 | E10: ='Scheda 6'!K44 | F10: ='Scheda 6'!O44 | G10: ='Scheda 6'!O45 | H10: =IF(F10>87,'Scheda 6'!AM$11,"non previsto") | I10: =IF(G10>140,'Scheda 6'!T$41,"non previsto") | J10: =IF(F10<80,"BASSA"," ") | K10: =IF(F10>85," ",IF(F10>80,"MEDIA",IF(F10<80," ",IF(F10<87," "," ")))) | L10: =IF(F10>85,"ALTA"," ") | M10: HAV | N10: NO | O10: NO
A11: ='Scheda 7'!F8 | B11: 7 | C11: ='Scheda 7'!H44 | D11: ='Scheda 7'!I44 | E11: ='Scheda 7'!K44 | F11: ='Scheda 7'!O44 | G11: ='Scheda 7'!O45 | H11: =IF(F11>87,'Scheda 7'!AM$11,"non previsto") | I11: =IF(G11>140,'Scheda 7'!T$41,"non previsto") | J11: =IF(F11<80,"BASSA"," ") | K11: =IF(F11>85," ",IF(F11>80,"MEDIA",IF(F11<80," ",IF(F11<87," "," ")))) | L11: =IF(F11>85,"ALTA"," ") | M11: HAV | N11: NO | O11: NO
A12: ='Scheda 8'!F8 | B12: 8 | C12: ='Scheda 8'!H44 | D12: ='Scheda 8'!I44 | E12: ='Scheda 8'!K44 | F12: ='Scheda 8'!O44 | G12: ='Scheda 8'!O45 | H12: =IF(F12>87,'Scheda 8'!AM$11,"non previsto") | I12: =IF(G12>140,'Scheda 8'!T$41,"non previsto") | J12: =IF(F12<80,"BASSA"," ") | K12: =IF(F12>85," ",IF(F12>80,"MEDIA",IF(F12<80," ",IF(F12<87," "," ")))) | L12: =IF(F12>85,"ALTA"," ") | M12: NO | N12: NO | O12: NO
A13: ='Scheda 9'!F8 | B13: 9 | C13: ='Scheda 8'!H44 | D13: ='Scheda 9'!I44 | E13: ='Scheda 9'!K44 | F13: ='Scheda 9'!O44 | G13: ='Scheda 9'!O45 | H13: =IF(F13>97,'Scheda 9'!AM$11,"non previsto") | I13: =IF(G13>140,'Scheda 9'!T$41,"non previsto") | J13: =IF(F13<80,"BASSA"," ") | K13: =IF(F13>85," ",IF(F13>80,"X",IF(F13<80," ",IF(F13<87," "," ")))) | L13: =IF(F13>85,"ALTA"," ") | M13: WBV | N13: NO | O13: NO
A14: ='Scheda 10'!F8 | B14: 10 | C14: ='Scheda 10'!H44 | D14: ='Scheda 10'!I44 | E14: ='Scheda 10'!K44 | F14: ='Scheda 10'!O44 | G14: ='Scheda 10'!O45 | H14: =IF(F14>87,'Scheda 10'!AM$11,"non previsto") | I14: =IF(G14>140,'Scheda 10'!T$41,"non previsto") | J14: =IF(F14<80,"BASSA"," ") | K14: =IF(F14>85," ",IF(F14>80,"X",IF(F14<80," ",IF(F14<87," "," ")))) | L14: =IF(F14>85,"ALTA"," ") | M14: HAV | N14: NO | O14: NO
A15: ='Scheda 11'!F8 | B15: 11 | C15: ='Scheda 11'!H44 | D15: ='Scheda 11'!I44 | E15: ='Scheda 11'!K44 | F15: ='Scheda 11'!O44 | G15: ='Scheda 11'!O45 | H15: =IF(F15>87,'Scheda 11'!AM$11,"non previsto") | I15: =IF(G15>140,'Scheda 11'!T$41,"non previsto") | J15: =IF(F15<80,"BASSA"," ") | K15: =IF(F15>85," ",IF(F15>80,"MEDIA",IF(F15<80," ",IF(F15<87," "," ")))) | L15: =IF(F15>85,"ALTA"," ") | M15: WBV | N15: NO | O15: NO
A16: ='Scheda 12'!F8 | B16: 12 | C16: ='Scheda 12'!H44 | D16: ='Scheda 12'!I44 | E16: ='Scheda 12'!K44 | F16: ='Scheda 12'!O44 | G16: ='Scheda 12'!O45 | H16: =IF(F16>87,'Scheda 12'!AM$11,"non previsto") | I16: =IF(G16>140,'Scheda 12'!T$41,"non previsto") | J16: =IF(F16<80,"BASSA"," ") | K16: =IF(F16>85," ",IF(F16>80,"X",IF(F16<80," ",IF(F16<87," "," ")))) | L16: =IF(F16>85,"ALTA"," ") | M16: WBV | N16: SI | O16: NO
A17: ='Scheda 13'!F8 | B17: 13 | C17: ='Scheda 13'!H44 | D17: ='Scheda 13'!I44 | E17: ='Scheda 13'!K44 | F17: ='Scheda 13'!O44 | G17: ='Scheda 13'!O45 | H17: =IF(F17>87,'Scheda 13'!AM$11,"non previsto") | I17: =IF(G17>140,'Scheda 13'!T$41,"non previsto") | J17: =IF(F17<80,"BASSA"," ") | K17: =IF(F17>85," ",IF(F17>80,"X",IF(F17<80," ",IF(F17<87," "," ")))) | L17: =IF(F17>85,"ALTA"," ") | M17: WBV-HAV | N17: SI | O17: NO
A18: ='Scheda 14'!F8 | B18: 14 | C18: ='Scheda 14'!H44 | D18: ='Scheda 14'!I44 | E18: ='Scheda 14'!K44 | F18: ='Scheda 14'!O44 | G18: ='Scheda 14'!O45 | H18: =IF(F18>87,'Scheda 14'!AM$11,"non previsto") | I18: =IF(G18>140,'Scheda 14'!T$41,"non previsto") | J18: =IF(F18<80,"BASSA"," ") | K18: =IF(F18>85," ",IF(F18>80,"X",IF(F18<80," ",IF(F18<87," "," ")))) | L18: =IF(F18>85,"ALTA"," ") | M18: WBV-HAV | N18: SI | O18: NO
A19: ='Scheda 15'!F8 | B19: 15 | C19: ='Scheda 2'!H44 | D19: ='Scheda 15'!I44 | E19: ='Scheda 15'!K44 | F19: ='Scheda 15'!O44 | G19: ='Scheda 15'!O45 | H19: =IF(F19>87,'Scheda 15'!AM$11,"non previsto") | I19: =IF(G19>140,'Scheda 15'!T$41,"non previsto") | J19: =IF(F19<80,"BASSA"," ") | K19: =IF(F19>85," ",IF(F19>80,"MEDIA",IF(F19<80," ",IF(F19<87," "," ")))) | L19: =IF(F19>85,"ALTA"," ") | M19: WBV | N19: NO | O19: NO
A20: ='Scheda 16'!F8 | B20: 16 | C20: ='Scheda 16'!H44 | D20: ='Scheda 16'!I44 | E20: ='Scheda 16'!K44 | F20: ='Scheda 16'!O44 | G20: ='Scheda 16'!O45 | H20: =IF(F20>87,'Scheda 16'!AM$11,"non previsto") | I20: =IF(G20>140,'Scheda 16'!T$41,"non previsto") | J20: =IF(F20<80,"BASSA"," ") | K20: =IF(F20>85," ",IF(F20>80,"X",IF(F20<80," ",IF(F20<87," "," ")))) | L20: =IF(F20>85,"ALTA"," ") | M20: HAV | N20: NO | O20: NO
A21: ='Scheda 17'!F8 | B21: 17 | C21: ='Scheda 4'!H44 | D21: ='Scheda 17'!I44 | E21: ='Scheda 17'!K44 | F21: ='Scheda 17'!O44 | G21: ='Scheda 17'!O45 | H21: =IF(F21>84,'Scheda 17'!AM$11,"non previsto") | I21: =IF(G21>140,'Scheda 17'!T$41,"non previsto") | J21: =IF(F21<80,"BASSA"," ") | K21: =IF(F21>85," ",IF(F21>80,"MEDIA",IF(F21<80," ",IF(F21<87," "," ")))) | L21: =IF(F21>85,"ALTA"," ") | M21: WBV | N21: NO | O21: NO
A22: ='Scheda 18'!F8 | B22: 18 | C22: ='Scheda 5'!H44 | D22: ='Scheda 18'!I44 | E22: ='Scheda 18'!K44 | F22: ='Scheda 18'!O44 | G22: ='Scheda 18'!O45 | H22: =IF(F22>87,'Scheda 18'!AM$11,"non previsto") | I22: =IF(G22>540,'Scheda 18'!T$45,"non previsto") | J22: =IF(F22<80,"BASSA"," ") | K22: =IF(F22>85," ",IF(F22>80,"X",IF(F22<80," ",IF(F22<87," "," ")))) | L22: =IF(F22>85,"ALTA"," ") | M22: WBV | N22: NO | O22: NO
A23: ='Scheda 19'!F8 | B23: 19 | C23: ='Scheda 6'!H44 | D23: ='Scheda 19'!I44 | E23: ='Scheda 19'!K44 | F23: ='Scheda 19'!O44 | G23: ='Scheda 19'!O45 | H23: =IF(F23>87,'Scheda 19'!AM$11,"non previsto") | I23: =IF(G23>140,'Scheda 19'!T$41,"non previsto") | J23: =IF(F23<80,"BASSA"," ") | K23: =IF(F23>85," ",IF(F23>80,"MEDIA",IF(F23<80," ",IF(F23<87," "," ")))) | L23: =IF(F23>85,"ALTA"," ") | M23: WBV | N23: NO | O23: NO
A24: ='Scheda 20'!F8 | B24: 20 | C24: ='Scheda 20'!H44 | D24: ='Scheda 20'!I44 | E24: ='Scheda 20'!K44 | F24: ='Scheda 20'!O44 | G24: ='Scheda 20'!O45 | H24: =IF(F24>87,'Scheda 20'!AM$11,"non previsto") | I24: =IF(G24>140,'Scheda 20'!T$41,"non previsto") | J24: =IF(F24<80,"BASSA"," ") | K24: =IF(F24>85," ",IF(F24>80,"X",IF(F24<80," ",IF(F24<87," "," ")))) | L24: =IF(F24>85,"ALTA"," ") | M24: HAV | N24: NO | O24: NO
A25: ='Scheda 21'!F8 | B25: 21 | C25: ='Scheda 21'!H44 | D25: ='Scheda 21'!I44 | E25: ='Scheda 21'!K44 | F25: ='Scheda 21'!O44 | G25: ='Scheda 21'!O45 | H25: =IF(F25>87,'Scheda 21'!AM$11,"non previsto") | I25: =IF(G25>140,'Scheda 21'!T$41,"non previsto") | J25: =IF(F25<80,"BASSA"," ") | K25: =IF(F25>85," ",IF(F25>80,"X",IF(F25<80," ",IF(F25<87," "," ")))) | L25: =IF(F25>85,"ALTA"," ") | M25: HAV | N25: NO | O25: NO
A26: ='Scheda 22'!F8 | B26: 22 | C26: ='Scheda 22'!H44 | D26: ='Scheda 22'!I44 | E26: ='Scheda 22'!K44 | F26: ='Scheda 22'!O44 | G26: ='Scheda 22'!O45 | H26: =IF(F26>87,'Scheda 22'!AM$11,"non previsto") | I26: =IF(G26>140,'Scheda 22'!T$41,"non previsto") | J26: =IF(F26<80,"BASSA"," ") | K26: =IF(F26>85," ",IF(F26>80,"X",IF(F26<80," ",IF(F26<87," "," ")))) | L26: =IF(F26>85,"ALTA"," ") | M26: NO | N26: NO | O26: NO
A27: ='Scheda 23'!F8 | B27: 23 | C27: ='Scheda 23'!H44 | D27: ='Scheda 23'!I44 | E27: ='Scheda 23'!K44 | F27: ='Scheda 23'!O44 | G27: ='Scheda 23'!O45 | H27: =IF(F27>87,'Scheda 23'!AM$11,"non previsto") | I27: =IF(G27>140,'Scheda 23'!T$41,"non previsto") | J27: =IF(F27<80,"BASSA"," ") | K27: =IF(F27>85," ",IF(F27>80,"MEDIA",IF(F27<80," ",IF(F27<87," "," ")))) | L27: =IF(F27>85,"ALTA"," ") | M27: NO | N27: NO | O27: NO
A28: ='Scheda 24'!F8 | B28: 24 | C28: ='Scheda 24'!H44 | D28: ='Scheda 24'!I44 | E28: ='Scheda 24'!K44 | F28: ='Scheda 24'!O44 | G28: ='Scheda 24'!O45 | H28: =IF(F30>87,'Scheda 24'!AM$11,"non previsto") | I28: =IF(G30>140,'Scheda 24'!T$41,"non previsto") | J28: =IF(F28<80,"BASSA"," ") | K28: =IF(F28>85," ",IF(F28>80,"MEDIA",IF(F28<80," ",IF(F28<87," "," ")))) | L28: =IF(F30>85,"X"," ") | M28: NO | N28: NO | O28: NO
A29: ='[1]Scheda 25'!F8 | B29: 25 | C29: ='[2]Scheda 25'!H44 | D29: ='[2]Scheda 25'!I44 | E29: ='[2]Scheda 25'!K44 | F29: ='[2]Scheda 25'!O44 | G29: ='[2]Scheda 25'!O45 | H29: =IF(F29>87,'[2]Scheda 25'!AM$11,"non previsto") | I29: =IF(G29>140,'[2]Scheda 25'!T$41,"non previsto") | J29: =IF(F29<80,"BASSA"," ") | K29: =IF(F29>85," ",IF(F29>80,"X",IF(F29<80," ",IF(F29<87," "," ")))) | L29: =IF(F29>85,"ALTA"," ") | M29: HAV | N29: NO | O29: NO
A30: ='[2]Scheda 26'!F8 | B30: 26 | C30: ='[2]Scheda 26'!H44 | D30: ='[2]Scheda 26'!I44 | E30: ='[2]Scheda 26'!K44 | F30: ='[2]Scheda 26'!O44 | G30: ='[2]Scheda 26'!O45 | H30: =IF(F30>87,'[2]Scheda 26'!AM$11,"non previsto") | I30: =IF(G30>140,'[2]Scheda 26'!T$41,"non previsto") | J30: =IF(F30<80,"BASSA"," ") | K30: =IF(F30>85," ",IF(F30>80,"MEDIA",IF(F30<80," ",IF(F30<87," "," ")))) | L30: =IF(F30>85,"X"," ") | M30: NO | N30: NO | O30: NO
A31: ='[2]Scheda 27'!F8 | B31: 27 | C31: ='[2]Scheda 27'!H44 | D31: ='[2]Scheda 27'!I44 | E31: ='[2]Scheda 27'!K44 | F31: ='[2]Scheda 27'!O44 | G31: ='[2]Scheda 27'!O45 | H31: =IF(F31>87,'[2]Scheda 27'!AM$11,"non previsto") | I31: =IF(G31>140,'[2]Scheda 27'!T$41,"non previsto") | J31: =IF(F31<80,"BASSA"," ") | K31: =IF(F31>85," ",IF(F31>80,"MEDIA",IF(F31<80," ",IF(F31<87," "," ")))) | L31: =IF(F31>85,"X"," ") | M31: NO | N31: NO | O31: NO
A32: ='[2]Scheda 28'!F8 | B32: 28 | C32: ='[2]Scheda 28'!H44 | D32: ='[2]Scheda 28'!I44 | E32: ='[2]Scheda 28'!K44 | F32: ='[2]Scheda 28'!O44 | G32: ='[2]Scheda 28'!O45 | H32: =IF(F32>87,'[2]Scheda 28'!AM$11,"non previsto") | I32: =IF(G32>140,'[2]Scheda 28'!T$41,"non previsto") | J32: =IF(F32<80,"BASSA"," ") | K32: =IF(F32>85," ",IF(F32>80,"MEDIA",IF(F32<80," ",IF(F32<87," "," ")))) | L32: =IF(F32>85,"X"," ") | M32: NO | N32: NO | O32: NO
A33: ='[2]Scheda 29'!$F$8 | B33: 29 | C33: ='[2]Scheda 29'!H44 | D33: ='[2]Scheda 29'!I44 | E33: ='[2]Scheda 29'!K44 | F33: ='[2]Scheda 29'!O44 | G33: ='[2]Scheda 29'!O45 | H33: =IF(F33>87,'[2]Scheda 29'!AM$11,"non previsto") | I33: =IF(G33>140,'[2]Scheda 29'!T$41,"non previsto") | J33: =IF(F33<80,"BASSA"," ") | K33: =IF(F33>85," ",IF(F33>80,"MEDIA",IF(F33<80," ",IF(F33<87," "," ")))) | L33: =IF(F33>85,"X"," ") | M33: NO | N33: NO | O33: NO
A34: ='[2]Scheda 30'!$F$8 | B34: 30 | C34: ='[2]Scheda 30'!H44 | D34: ='[2]Scheda 30'!I44 | E34: ='[2]Scheda 30'!K44 | F34: ='[2]Scheda 30'!O44 | G34: ='[2]Scheda 30'!O45 | H34: =IF(F34>87,'[2]Scheda 30'!AM$11,"non previsto") | I34: =IF(G34>140,'[2]Scheda 30'!T$41,"non previsto") | J34: =IF(F34<80,"BASSA"," ") | K34: =IF(F34>85," ",IF(F34>80,"MEDIA",IF(F34<80," ",IF(F34<87," "," ")))) | L34: =IF(F34>85,"X"," ") | M34: WBV | N34: NO | O34: NO
A35: ='[2]Scheda 31'!$F$8 | B35: 31 | C35: ='[2]Scheda 31'!H44 | D35: ='[2]Scheda 31'!I44 | E35: ='[2]Scheda 31'!K44 | F35: ='[2]Scheda 31'!O44 | G35: ='[2]Scheda 31'!O45 | H35: =IF(F35>87,'[2]Scheda 31'!AM$11,"non previsto") | I35: =IF(G35>140,'[2]Scheda 31'!T$41,"non previsto") | J35: =IF(F35<80,"BASSA"," ") | K35: =IF(F35>85," ",IF(F35>80,"X",IF(F35<80," ",IF(F35<87," "," ")))) | L35: =IF(F35>85,"X"," ") | M35: NO | N35: NO | O35: NO
A36: ='[2]Scheda 32'!$F$8 | B36: 32 | C36: ='[2]Scheda 32'!H44 | D36: ='[2]Scheda 32'!I44 | E36: ='[2]Scheda 32'!K44 | F36: ='[2]Scheda 32'!O44 | G36: ='[2]Scheda 32'!O45 | H36: =IF(F36>87,'[2]Scheda 32'!AM$11,"non previsto") | I36: =IF(G36>140,'[2]Scheda 32'!T$41,"non previsto") | J36: =IF(F36<80,"BASSA"," ") | K36: =IF(F36>85," ",IF(F36>80,"MEDIA",IF(F36<80," ",IF(F36<87," "," ")))) | L36: =IF(F36>85,"X"," ") | M36: HAV | N36: NO | O36: NO
A37: ='[2]Scheda 33'!$F$8 | B37: 33 | C37: ='[2]Scheda 33'!H44 | D37: ='[2]Scheda 33'!I44 | E37: ='[2]Scheda 33'!K44 | F37: ='[2]Scheda 33'!O44 | G37: ='[2]Scheda 33'!O45 | H37: =IF(F37>87,'[2]Scheda 33'!AM$11,"non previsto") | I37: =IF(G37>140,'[2]Scheda 33'!T$41,"non previsto") | J37: =IF(F37<80,"BASSA"," ") | K37: =IF(F37>85," ",IF(F37>80,"X",IF(F37<80," ",IF(F37<87," "," ")))) | L37: =IF(F37>85,"X"," ") | M37: NO | N37: NO | O37: NO
A38: ='[2]Scheda 34'!$F$8 | B38: 34 | C38: ='[2]Scheda 34'!H44 | D38: ='[2]Scheda 34'!I44 | E38: ='[2]Scheda 34'!K44 | F38: ='[2]Scheda 34'!O44 | G38: ='[2]Scheda 34'!O45 | H38: =IF(F38>87,'[2]Scheda 34'!AM$11,"non previsto") | I38: =IF(G38>140,'[2]Scheda 34'!T$41,"non previsto") | J38: =IF(F38<80,"BASSA"," ") | K38: =IF(F38>85," ",IF(F38>80,"X",IF(F38<80," ",IF(F38<87," "," ")))) | L38: =IF(F38>85,"ALTA"," ") | M38: HAV | N38: NO | O38: NO
A39: ='[2]Scheda 35'!$F$8 | B39: 35 | C39: ='[2]Scheda 35'!H44 | D39: ='[2]Scheda 35'!I44 | E39: ='[2]Scheda 35'!K44 | F39: ='[2]Scheda 35'!O44 | G39: ='[2]Scheda 35'!O45 | H39: =IF(F39>87,'[2]Scheda 35'!AM$11,"non previsto") | I39: =IF(G39>140,'[2]Scheda 35'!T$41,"non previsto")
A40: ='[2]Scheda 36'!$F$8 | B40: 36 | C40: ='[2]Scheda 36'!H44 | D40: ='[2]Scheda 36'!I44 | E40: ='[2]Scheda 36'!K44 | F40: ='[2]Scheda 36'!O44 | G40: ='[2]Scheda 36'!O45 | H40: =IF(F40>87,'[2]Scheda 36'!AM$11,"non previsto") | I40: =IF(G40>140,'[2]Scheda 36'!T$41,"non previsto")
A41: ='[2]Scheda 37'!$F$8 | B41: 37 | C41: ='[2]Scheda 4'!H44 | D41: ='[2]Scheda 37'!I44 | E41: ='[2]Scheda 37'!K44 | F41: ='[2]Scheda 37'!O44 | G41: ='[2]Scheda 37'!O45 | H41: =IF(F41>84,'[2]Scheda 37'!AM$11,"non previsto") | I41: =IF(G41>140,'[2]Scheda 37'!T$41,"non previsto")
A42: ='[2]Scheda 38'!$F$8 | B42: 38 | C42: ='[2]Scheda 5'!H44 | D42: ='[2]Scheda 38'!I44 | E42: ='[2]Scheda 38'!K44 | F42: ='[2]Scheda 38'!O44 | G42: ='[2]Scheda 38'!O45 | H42: =IF(F42>87,'[2]Scheda 38'!AM$11,"non previsto") | I42: =IF(G42>540,'[2]Scheda 38'!T$45,"non previsto")
A43: ='[2]Scheda 39'!$F$8 | B43: 39 | C43: ='[2]Scheda 6'!H44 | D43: ='[2]Scheda 39'!I44 | E43: ='[2]Scheda 39'!K44 | F43: ='[2]Scheda 39'!O44 | G43: ='[2]Scheda 39'!O45 | H43: =IF(F43>87,'[2]Scheda 39'!AM$11,"non previsto") | I43: =IF(G43>140,'[2]Scheda 39'!T$41,"non previsto")
...

Sheet Tab-Mis (3)
A1: TITOLO VIII - Capo II del D.Lgs 81/2008 -- VALUTAZIONE DELL'ESPOSIZIONE AD AGENTI FISICI (RUMORE) -- "ALLEGATO 1 - TABELLA MISURE" | C1: TITOLO VIII - Capo II del D.Lgs 81/2008 -- VALUTAZIONE DELL'ESPOSIZIONE AD AGENTI FISICI (RUMORE) -- ALLEGATO 1 - TABELLA MISURE (UNI EN ISO 9612:2011 e UNI 9432:2011) | AU1: Verifica idoneità D.P.I. per sorgente sonora (anche in conformità all'art. 191. c.1 D.Lgs 81/08)
A3: Cod. PKL. | B3: ID | C3: Categoria | D3: Marca | E3: Modello | F3: Lavorazione e caratterisitche macchina attrezzatura | G3: Data Misurazioni | H3: Strategia di misura COMPITO MANSIONI GIORNATA | I3: Tipo di rumore | N3: PPEAK(C) + U(Lpicco,C) | O3: LAEQ,Tp | P3: LCEQ,TP | Q3: MISURA n°1 | W3: MISURA n°2 | AA3: MISURA n°3 | AE3: MISURA n°4 | AI3: MISURA n°5 | AM3: MISURA n°6 | AQ3: Necessità di perimetrazione dell'area | AR3: T max Inf. | AS3: T max Sup. | AT3: T max Lim. | AU3: ='DPI art.191'!B2 | AV3: ='DPI art.191'!C2 | AW3: ='DPI art.191'!D2 | AX3: ='DPI art.191'!B4 | AY3: ='DPI art.191'!C4 | AZ3: ='DPI art.191'!D4 | BA3: ='DPI art.191'!B6 | BB3: ='DPI art.191'!C6 | BC3: ='DPI art.191'!D6 | BD3: ='DPI art.191'!B8 | BE3: ='DPI art.191'!C8 | BF3: ='DPI art.191'!D8 | BG3: Esponenziale Lp,A,eq,tm | BM3: Differenza Leq medio - Leq,i | BU3: Quadrati degli scarti Leq medio - Leq,i
I4: I | J4: F | K4: S | L4: C | M4: U1a,m | Q4: Sec. | R4: LAeq,T | S4: LCeq,T | T4: Lpicco,C | U4: LAS(t) | V4: LAeq,I,T | W4: Sec. | X4: LAeq,T | Y4: LCeq,T | Z4: Lpicco,C | AA4: Sec. | AB4: LAeq,T | AC4: LCeq,T | AD4: Lpicco,C | AE4: Sec. | AF4: LAeq,T | AG4: LCeq,T | AH4: Lpicco,C | AI4: Sec. | AJ4: LAeq,T | AK4: LCeq,T | AL4: Lpicco,C | AM4: Sec. | AN4: LAeq,T | AO4: LCeq,T | AP4: Lpicco,C | AU4: PNR | AV4: L'Aeq,T | AW4: Picco | AX4: PNR | AY4: L'Aeq,T | AZ4: Picco | BA4: PNR | BB4: L'Aeq,T | BC4: Picco | BD4: PNR | BE4: L'Aeq,T | BF4: Picco | BG4: 1 | BH4: 2 | BI4: 3 | BJ4: 4 | BK4: 5 | BL4: 6 | BM4: 1 | BN4: 2 | BO4: 3 | BP4: 4 | BQ4: 5 | BR4: 6 | BS4: N°campioni | BT4: U1a (I terrm.) | BU4: 1 | BV4: 2 | BW4: 3 | BX4: 4 | BY4: 5 | BZ4: 6
B5: ⌂
A6: Gualdo 1 | B6: W1 | C6: Fresa diritta | D6: URYU | E6: UG-65 | F6: Molatura con mola assiale | G6: 45996 | H6: Compito | I6: =IF((V6-R6)>3,"SI","") | J6: SI | M6: =IF(R6>0,(SQRT(BT6*(SUM(BU6:BZ6)))),"") | N6: =IF(T6>0,(MAX(T6,Z6,AD6,AH6,AL6,AP6))+SQRT(1.2^2+1^2),"") | O6: =IF(R6="",0,10*LOG10(SUM(BG6:BL6)/(COUNT(R6,X6,AB6,AF6,AJ6,AN6)))) | P6: =IF(AND(Y6="",AC6="",AG6="",AK6="",AO6=""),S6,AVERAGE(S6,Y6,AC6,AG6,AK6,AO6)+STDEV(S6,Y6,AC6,AG6,AK6,AO6)) | Q6: 300 | R6: 98.6 | S6: 98.3 | T6: 120.7 | W6: 300 | X6: 98.6 | Y6: 97.8 | Z6: 119.4 | AA6: 300 | AB6: 98.1 | AC6: 96.9 | AD6: 117.8 | AE6: 300 | AF6: 93.7 | AG6: 93.1 | AH6: 117.2 | AI6: 300 | AJ6: 100.3 | AK6: 99.2 | AL6: 116 | AM6: 300 | AN6: 96.8 | AO6: 95.6 | AP6: 120.8 | AQ6: =IF(AND((O6)<85,N6<137),"NO","SI") | AR6: =IF((480*(10^(7.95-(O6/10))))<480,480*(10^(7.95-(O6/10))),480) | AS6: =IF((480*(10^(8.45-(O6/10))))<480,480*(10^(8.45-(O6/10))),480) | AT6: =IF((480*(10^(8.65-(O6/10))))<480,480*(10^(8.65-(O6/10))),480) | AU6: =IF(O6<80,"0",IF((P6-O6)<=2,('DPI art.191'!$G$3-(('DPI art.191'!$F$3-'DPI art.191'!$G$3)/4)*(P6-O6-2)),('DPI art.191'!$G$3-(('DPI art.191'!$F$3-'DPI art.191'!$H$3)/8)*(P6-O6-2)))) | AV6: =O6-AU6 | AW6: =IF(N6<135,N6,N6-'DPI art.191'!$I$3) | AX6: =IF(I6<80,"0",IF((J6-I6)<=2,('DPI art.191'!$G$7-(('DPI art.191'!$F$7-'DPI art.191'!$G$7)/4)*(I6-J6-2)),('DPI art.191'!$G$7-(('DPI art.191'!$G$7-'DPI art.191'!$H$7)/8)*(J6-I6-2)))) | AY6: =I6-AX6 | AZ6: =IF(H6<135,H6,H6-'DPI art.191'!$I$7) | BA6: =IF(O6<80,"0",IF((P6-O6)<=2,('DPI art.191'!$G$5-(('DPI art.191'!$F$5-'DPI art.191'!$G$5)/4)*(P6-O6-2)),('DPI art.191'!$G$5-(('DPI art.191'!$G$5-'DPI art.191'!$H$5)/8)*(P6-O6-2)))) | BB6: =R6-BA6 | BC6: =IF(N6<135,N6,N6-'DPI art.191'!$I$5) | BD6: =IF(O6<80,"0",IF((P6-O6)<=2,('DPI art.191'!$G$7-(('DPI art.191'!$F$7-'DPI art.191'!$G$7)/4)*(O6-P6-2)),('DPI art.191'!$G$7-(('DPI art.191'!$G$7-'DPI art.191'!$H$7)/8)*(P6-O6-2)))) | BE6: =O6-BD6 | BF6: =IF(N6<135,N6,N6-'DPI art.191'!$I$7) | BG6: =10^(0.1*R6) | BH6: =10^(0.1*X6) | BI6: =10^(0.1*AB6) | BJ6: =10^(0.1*AF6) | BK6: =10^(0.1*AJ6) | BL6: =10^(0.1*AN6) | BM6: =IF(R6>0,(O6-R6),"") | BN6: =IF(X6>0,(O6-X6),"") | BO6: =IF(AB6>0,(O6-AB6),"") | BP6: =IF(AF6>0,(O6-AF6),"") | BQ6: =IF(AJ6>0,(O6-AJ6),"") | BR6: =IF(AN6>0,(O6-AN6),"") | BS6: =COUNT(BM6:BR6) | BT6: =IF(BS6=0,0,IF(BS6=1,0,1/(BS6*(BS6-1)))) | BU6: =IF(R6>0,(BM6^2),"") | BV6: =IF(X6>0,(BN6^2),"") | BW6: =IF(AB6>0,(BO6^2),"") | BX6: =IF(AF6>0,(BP6^2),"") | BY6: =IF(AJ6>0,(BQ6^2),"") | BZ6: =IF(AN6>0,(BR6^2),"")
A7: 024/B/PRS767 | B7: W2 | C7: Saldatrice a filo | D7: MILLER | E7: Pipeworx 400 Power - Pipeworx Dual Bench Feeder | F7: Saldatura | G7: 45996 | H7: Compito | I7: =IF((V7-R7)>3,"SI","") | J7: SI | M7: =IF(R7>0,(SQRT(BT7*(SUM(BU7:BZ7)))),"") | N7: =IF(T7>0,(MAX(T7,Z7,AD7,AH7,AL7,AP7))+SQRT(1.2^2+1^2),"") | O7: =IF(R7="",0,10*LOG10(SUM(BG7:BL7)/(COUNT(R7,X7,AB7,AF7,AJ7,AN7)))) | P7: =IF(AND(Y7="",AC7="",AG7="",AK7="",AO7=""),S7,AVERAGE(S7,Y7,AC7,AG7,AK7,AO7)+STDEV(S7,Y7,AC7,AG7,AK7,AO7)) | Q7: 300 | R7: 88.7 | S7: 87.9 | T7: 118.3 | W7: 300 | X7: 91.9 | Y7: 91.4 | Z7: 116.7 | AA7: 300 | AB7: 80.5 | AC7: 82.8 | AD7: 113.7 | AE7: 300 | AF7: 90.3 | AG7: 90.3 | AH7: 117.7 | AI7: 300 | AJ7: 93.4 | AK7: 92.7 | AL7: 117.5 | AM7: 300 | AN7: 98 | AO7: 96.6 | AP7: 122.9 | AQ7: =IF(AND((O7)<85,N7<137),"NO","SI") | AR7: =IF((480*(10^(7.95-(O7/10))))<480,480*(10^(7.95-(O7/10))),480) | AS7: =IF((480*(10^(8.45-(O7/10))))<480,480*(10^(8.45-(O7/10))),480) | AT7: =IF((480*(10^(8.65-(O7/10))))<480,480*(10^(8.65-(O7/10))),480) | AU7: =IF(O7<80,"0",IF((P7-O7)<=2,('DPI art.191'!$G$3-(('DPI art.191'!$F$3-'DPI art.191'!$G$3)/4)*(P7-O7-2)),('DPI art.191'!$G$3-(('DPI art.191'!$F$3-'DPI art.191'!$H$3)/8)*(P7-O7-2)))) | AV7: =O7-AU7 | AW7: =IF(N7<135,N7,N7-'DPI art.191'!$I$3) | AX7: =IF(I7<80,"0",IF((J7-I7)<=2,('DPI art.191'!$G$7-(('DPI art.191'!$F$7-'DPI art.191'!$G$7)/4)*(I7-J7-2)),('DPI art.191'!$G$7-(('DPI art.191'!$G$7-'DPI art.191'!$H$7)/8)*(J7-I7-2)))) | AY7: =I7-AX7 | AZ7: =IF(H7<135,H7,H7-'DPI art.191'!$I$7) | BA7: =IF(O7<80,"0",IF((P7-O7)<=2,('DPI art.191'!$G$5-(('DPI art.191'!$F$5-'DPI art.191'!$G$5)/4)*(P7-O7-2)),('DPI art.191'!$G$5-(('DPI art.191'!$G$5-'DPI art.191'!$H$5)/8)*(P7-O7-2)))) | BB7: =R7-BA7 | BC7: =IF(N7<135,N7,N7-'DPI art.191'!$I$5) | BD7: =IF(O7<80,"0",IF((P7-O7)<=2,('DPI art.191'!$G$7-(('DPI art.191'!$F$7-'DPI art.191'!$G$7)/4)*(O7-P7-2)),('DPI art.191'!$G$7-(('DPI art.191'!$G$7-'DPI art.191'!$H$7)/8)*(P7-O7-2)))) | BE7: =O7-BD7 | BF7: =IF(N7<135,N7,N7-'DPI art.191'!$I$7) | BG7: =10^(0.1*R7) | BH7: =10^(0.1*X7) | BI7: =10^(0.1*AB7) | BJ7: =10^(0.1*AF7) | BK7: =10^(0.1*AJ7) | BL7: =10^(0.1*AN7) | BM7: =IF(R7>0,(O7-R7),"") | BN7: =IF(X7>0,(O7-X7),"") | BO7: =IF(AB7>0,(O7-AB7),"") | BP7: =IF(AF7>0,(O7-AF7),"") | BQ7: =IF(AJ7>0,(O7-AJ7),"") | BR7: =IF(AN7>0,(O7-AN7),"") | BS7: =COUNT(BM7:BR7) | BT7: =IF(BS7=0,0,IF(BS7=1,0,1/(BS7*(BS7-1)))) | BU7: =IF(R7>0,(BM7^2),"") | BV7: =IF(X7>0,(BN7^2),"") | BW7: =IF(AB7>0,(BO7^2),"") | BX7: =IF(AF7>0,(BP7^2),"") | BY7: =IF(AJ7>0,(BQ7^2),"") | BZ7: =IF(AN7>0,(BR7^2),"")
A8: 017/1241 | B8: W3 | C8: Mola piccola | D8: FEIN | E8: GC17 | F8: Molatura con mola piccola | G8: 45996 | H8: Compito | I8: =IF((V8-R8)>3,"SI","") | J8: SI | M8: =IF(R8>0,(SQRT(BT8*(SUM(BU8:BZ8)))),"") | N8: =IF(T8>0,(MAX(T8,Z8,AD8,AH8,AL8,AP8))+SQRT(1.2^2+1^2),"") | O8: =IF(R8="",0,10*LOG10(SUM(BG8:BL8)/(COUNT(R8,X8,AB8,AF8,AJ8,AN8)))) | P8: =IF(AND(Y8="",AC8="",AG8="",AK8="",AO8=""),S8,AVERAGE(S8,Y8,AC8,AG8,AK8,AO8)+STDEV(S8,Y8,AC8,AG8,AK8,AO8)) | Q8: 300 | R8: 93.9 | S8: 93.9 | T8: 121.1 | W8: 300 | X8: 92.9 | Y8: 92.6 | Z8: 119.6 | AA8: 300 | AB8: 98.3 | AC8: 98.4 | AD8: 124.2 | AE8: 300 | AF8: 97.7 | AG8: 96.5 | AH8: 126.1 | AI8: 300 | AJ8: 102.7 | AK8: 101.2 | AL8: 120.5 | AM8: 300 | AN8: 98.5 | AO8: 97 | AP8: 120.3 | AQ8: =IF(AND((O8)<85,N8<137),"NO","SI") | AR8: =IF((480*(10^(7.95-(O8/10))))<480,480*(10^(7.95-(O8/10))),480) | AS8: =IF((480*(10^(8.45-(O8/10))))<480,480*(10^(8.45-(O8/10))),480) | AT8: =IF((480*(10^(8.65-(O8/10))))<480,480*(10^(8.65-(O8/10))),480) | AU8: =IF(O8<80,"0",IF((P8-O8)<=2,('DPI art.191'!$G$3-(('DPI art.191'!$F$3-'DPI art.191'!$G$3)/4)*(P8-O8-2)),('DPI art.191'!$G$3-(('DPI art.191'!$F$3-'DPI art.191'!$H$3)/8)*(P8-O8-2)))) | AV8: =O8-AU8 | AW8: =IF(N8<135,N8,N8-'DPI art.191'!$I$3) | AX8: =IF(I8<80,"0",IF((J8-I8)<=2,('DPI art.191'!$G$7-(('DPI art.191'!$F$7-'DPI art.191'!$G$7)/4)*(I8-J8-2)),('DPI art.191'!$G$7-(('DPI art.191'!$G$7-'DPI art.191'!$H$7)/8)*(J8-I8-2)))) | AY8: =I8-AX8 | AZ8: =IF(H8<135,H8,H8-'DPI art.191'!$I$7) | BA8: =IF(O8<80,"0",IF((P8-O8)<=2,('DPI art.191'!$G$5-(('DPI art.191'!$F$5-'DPI art.191'!$G$5)/4)*(P8-O8-2)),('DPI art.191'!$G$5-(('DPI art.191'!$G$5-'DPI art.191'!$H$5)/8)*(P8-O8-2)))) | BB8: =R8-BA8 | BC8: =IF(N8<135,N8,N8-'DPI art.191'!$I$5) | BD8: =IF(O8<80,"0",IF((P8-O8)<=2,('DPI art.191'!$G$7-(('DPI art.191'!$F$7-'DPI art.191'!$G$7)/4)*(O8-P8-2)),('DPI art.191'!$G$7-(('DPI art.191'!$G$7-'DPI art.191'!$H$7)/8)*(P8-O8-2)))) | BE8: =O8-BD8 | BF8: =IF(N8<135,N8,N8-'DPI art.191'!$I$7) | BG8: =10^(0.1*R8) | BH8: =10^(0.1*X8) | BI8: =10^(0.1*AB8) | BJ8: =10^(0.1*AF8) | BK8: =10^(0.1*AJ8) | BL8: =10^(0.1*AN8) | BM8: =IF(R8>0,(O8-R8),"") | BN8: =IF(X8>0,(O8-X8),"") | BO8: =IF(AB8>0,(O8-AB8),"") | BP8: =IF(AF8>0,(O8-AF8),"") | BQ8: =IF(AJ8>0,(O8-AJ8),"") | BR8: =IF(AN8>0,(O8-AN8),"") | BS8: =COUNT(BM8:BR8) | BT8: =IF(BS8=0,0,IF(BS8=1,0,1/(BS8*(BS8-1)))) | BU8: =IF(R8>0,(BM8^2),"") | BV8: =IF(X8>0,(BN8^2),"") | BW8: =IF(AB8>0,(BO8^2),"") | BX8: =IF(AF8>0,(BP8^2),"") | BY8: =IF(AJ8>0,(BQ8^2),"") | BZ8: =IF(AN8>0,(BR8^2),"")
A9: 275/07 | B9: W4 | C9: Smussatrice | D9: TRIUMPH | E9: UZ 50 | F9: Smussatura | G9: 45996 | H9: Compito | I9: =IF((V9-R9)>3,"SI","") | J9: SI | M9: =IF(R9>0,(SQRT(BT9*(SUM(BU9:BZ9)))),"") | N9: =IF(T9>0,(MAX(T9,Z9,AD9,AH9,AL9,AP9))+SQRT(1.2^2+1^2),"") | O9: =IF(R9="",0,10*LOG10(SUM(BG9:BL9)/(COUNT(R9,X9,AB9,AF9,AJ9,AN9)))) | P9: =IF(AND(Y9="",AC9="",AG9="",AK9="",AO9=""),S9,AVERAGE(S9,Y9,AC9,AG9,AK9,AO9)+STDEV(S9,Y9,AC9,AG9,AK9,AO9)) | Q9: 300 | R9: 94.5 | S9: 95 | T9: 121.2 | W9: 300 | X9: 91.8 | Y9: 92.6 | Z9: 115.9 | AA9: 300 | AB9: 92.3 | AC9: 92.9 | AD9: 117.4 | AE9: 300 | AF9: 94.5 | AG9: 94 | AH9: 121.1 | AI9: 300 | AJ9: 93.5 | AK9: 95 | AL9: 121.4 | AM9: 300 | AN9: 94.6 | AO9: 94.2 | AP9: 121.2 | AQ9: =IF(AND((O9)<85,N9<137),"NO","SI") | AR9: =IF((480*(10^(7.95-(O9/10))))<480,480*(10^(7.95-(O9/10))),480) | AS9: =IF((480*(10^(8.45-(O9/10))))<480,480*(10^(8.45-(O9/10))),480) | AT9: =IF((480*(10^(8.65-(O9/10))))<480,480*(10^(8.65-(O9/10))),480) | AU9: =IF(O9<80,"0",IF((P9-O9)<=2,('DPI art.191'!$G$3-(('DPI art.191'!$F$3-'DPI art.191'!$G$3)/4)*(P9-O9-2)),('DPI art.191'!$G$3-(('DPI art.191'!$F$3-'DPI art.191'!$H$3)/8)*(P9-O9-2)))) | AV9: =O9-AU9 | AW9: =IF(N9<135,N9,N9-'DPI art.191'!$I$3) | AX9: =IF(I9<80,"0",IF((J9-I9)<=2,('DPI art.191'!$G$7-(('DPI art.191'!$F$7-'DPI art.191'!$G$7)/4)*(I9-J9-2)),('DPI art.191'!$G$7-(('DPI art.191'!$G$7-'DPI art.191'!$H$7)/8)*(J9-I9-2)))) | AY9: =I9-AX9 | AZ9: =IF(H9<135,H9,H9-'DPI art.191'!$I$7) | BA9: =IF(O9<80,"0",IF((P9-O9)<=2,('DPI art.191'!$G$5-(('DPI art.191'!$F$5-'DPI art.191'!$G$5)/4)*(P9-O9-2)),('DPI art.191'!$G$5-(('DPI art.191'!$G$5-'DPI art.191'!$H$5)/8)*(P9-O9-2)))) | BB9: =R9-BA9 | BC9: =IF(N9<135,N9,N9-'DPI art.191'!$I$5) | BD9: =IF(O9<80,"0",IF((P9-O9)<=2,('DPI art.191'!$G$7-(('DPI art.191'!$F$7-'DPI art.191'!$G$7)/4)*(O9-P9-2)),('DPI art.191'!$G$7-(('DPI art.191'!$G$7-'DPI art.191'!$H$7)/8)*(P9-O9-2)))) | BE9: =O9-BD9 | BF9: =IF(N9<135,N9,N9-'DPI art.191'!$I$7) | BG9: =10^(0.1*R9) | BH9: =10^(0.1*X9) | BI9: =10^(0.1*AB9) | BJ9: =10^(0.1*AF9) | BK9: =10^(0.1*AJ9) | BL9: =10^(0.1*AN9) | BM9: =IF(R9>0,(O9-R9),"") | BN9: =IF(X9>0,(O9-X9),"") | BO9: =IF(AB9>0,(O9-AB9),"") | BP9: =IF(AF9>0,(O9-AF9),"") | BQ9: =IF(AJ9>0,(O9-AJ9),"") | BR9: =IF(AN9>0,(O9-AN9),"") | BS9: =COUNT(BM9:BR9) | BT9: =IF(BS9=0,0,IF(BS9=1,0,1/(BS9*(BS9-1)))) | BU9: =IF(R9>0,(BM9^2),"") | BV9: =IF(X9>0,(BN9^2),"") | BW9: =IF(AB9>0,(BO9^2),"") | BX9: =IF(AF9>0,(BP9^2),"") | BY9: =IF(AJ9>0,(BQ9^2),"") | BZ9: =IF(AN9>0,(BR9^2),"")
A10: 017/1419 | B10: W5 | C10: Mola piccola | D10: FEIN | E10: CG17-150 | F10: Molatura con mola piccola | G10: 45996 | H10: Compito | I10: =IF((V10-R10)>3,"SI","") | J10: SI | M10: =IF(R10>0,(SQRT(BT10*(SUM(BU10:BZ10)))),"") | N10: =IF(T10>0,(MAX(T10,Z10,AD10,AH10,AL10,AP10))+SQRT(1.2^2+1^2),"") | O10: =IF(R10="",0,10*LOG10(SUM(BG10:BL10)/(COUNT(R10,X10,AB10,AF10,AJ10,AN10)))) | P10: =IF(AND(Y10="",AC10="",AG10="",AK10="",AO10=""),S10,AVERAGE(S10,Y10,AC10,AG10,AK10,AO10)+STDEV(S10,Y10,AC10,AG10,AK10,AO10)) | Q10: 300 | R10: 103 | S10: 101.5 | T10: 125.9 | W10: 300 | X10: 101.8 | Y10: 100.2 | Z10: 130.5 | AA10: 300 | AB10: 98.3 | AC10: 96.8 | AD10: 125.9 | AE10: 300 | AF10: 106.3 | AG10: 104.7 | AH10: 125.3 | AI10: 300 | AJ10: 105.5 | AK10: 104 | AL10: 128.3 | AM10: 300 | AN10: 95.6 | AO10: 94.5 | AP10: 124.3 | AQ10: =IF(AND((O10)<85,N10<137),"NO","SI") | AR10: =IF((480*(10^(7.95-(O10/10))))<480,480*(10^(7.95-(O10/10))),480) | AS10: =IF((480*(10^(8.45-(O10/10))))<480,480*(10^(8.45-(O10/10))),480) | AT10: =IF((480*(10^(8.65-(O10/10))))<480,480*(10^(8.65-(O10/10))),480) | AU10: =IF(O10<80,"0",IF((P10-O10)<=2,('DPI art.191'!$G$3-(('DPI art.191'!$F$3-'DPI art.191'!$G$3)/4)*(P10-O10-2)),('DPI art.191'!$G$3-(('DPI art.191'!$F$3-'DPI art.191'!$H$3)/8)*(P10-O10-2)))) | AV10: =O10-AU10 | AW10: =IF(N10<135,N10,N10-'DPI art.191'!$I$3) | AX10: =IF(I10<80,"0",IF((J10-I10)<=2,('DPI art.191'!$G$7-(('DPI art.191'!$F$7-'DPI art.191'!$G$7)/4)*(I10-J10-2)),('DPI art.191'!$G$7-(('DPI art.191'!$G$7-'DPI art.191'!$H$7)/8)*(J10-I10-2)))) | AY10: =I10-AX10 | AZ10: =IF(H10<135,H10,H10-'DPI art.191'!$I$7) | BA10: =IF(O10<80,"0",IF((P10-O10)<=2,('DPI art.191'!$G$5-(('DPI art.191'!$F$5-'DPI art.191'!$G$5)/4)*(P10-O10-2)),('DPI art.191'!$G$5-(('DPI art.191'!$G$5-'DPI art.191'!$H$5)/8)*(P10-O10-2)))) | BB10: =R10-BA10 | BC10: =IF(N10<135,N10,N10-'DPI art.191'!$I$5) | BD10: =IF(O10<80,"0",IF((P10-O10)<=2,('DPI art.191'!$G$7-(('DPI art.191'!$F$7-'DPI art.191'!$G$7)/4)*(O10-P10-2)),('DPI art.191'!$G$7-(('DPI art.191'!$G$7-'DPI art.191'!$H$7)/8)*(P10-O10-2)))) | BE10: =O10-BD10 | BF10: =IF(N10<135,N10,N10-'DPI art.191'!$I$7) | BG10: =10^(0.1*R10) | BH10: =10^(0.1*X10) | BI10: =10^(0.1*AB10) | BJ10: =10^(0.1*AF10) | BK10: =10^(0.1*AJ10) | BL10: =10^(0.1*AN10) | BM10: =IF(R10>0,(O10-R10),"") | BN10: =IF(X10>0,(O10-X10),"") | BO10: =IF(AB10>0,(O10-AB10),"") | BP10: =IF(AF10>0,(O10-AF10),"") | BQ10: =IF(AJ10>0,(O10-AJ10),"") | BR10: =IF(AN10>0,(O10-AN10),"") | BS10: =COUNT(BM10:BR10) | BT10: =IF(BS10=0,0,IF(BS10=1,0,1/(BS10*(BS10-1)))) | BU10: =IF(R10>0,(BM10^2),"") | BV10: =IF(X10>0,(BN10^2),"") | BW10: =IF(AB10>0,(BO10^2),"") | BX10: =IF(AF10>0,(BP10^2),"") | BY10: =IF(AJ10>0,(BQ10^2),"") | BZ10: =IF(AN10>0,(BR10^2),"")
A11: 024/B/PRS809 | B11: W6 | C11: Saldatrice a filo | D11: ESAB | E11: ARISTO 500X | F11: Saldatura interna gambe in piattaforma | G11: 45996 | H11: Compito | I11: =IF((V11-R11)>3,"SI","") | J11: SI | M11: =IF(R11>0,(SQRT(BT11*(SUM(BU11:BZ11)))),"") | N11: =IF(T11>0,(MAX(T11,Z11,AD11,AH11,AL11,AP11))+SQRT(1.2^2+1^2),"") | O11: =IF(R11="",0,10*LOG10(SUM(BG11:BL11)/(COUNT(R11,X11,AB11,AF11,AJ11,AN11)))) | P11: =IF(AND(Y11="",AC11="",AG11="",AK11="",AO11=""),S11,AVERAGE(S11,Y11,AC11,AG11,AK11,AO11)+STDEV(S11,Y11,AC11,AG11,AK11,AO11)) | Q11: 300 | R11: 86.1 | S11: 88.1 | T11: 125.6 | W11: 300 | X11: 84.4 | Y11: 87.9 | Z11: 123 | AA11: 300 | AB11: 87.3 | AC11: 89.9 | AD11: 119.6 | AE11: 300 | AF11: 102.5 | AG11: 101.1 | AH11: 127.5 | AI11: 300 | AJ11: 89.8 | AK11: 90 | AL11: 115.4 | AM11: 300 | AN11: 85.9 | AO11: 86.1 | AP11: 121.3 | AQ11: =IF(AND((O11)<85,N11<137),"NO","SI") | AR11: =IF((480*(10^(7.95-(O11/10))))<480,480*(10^(7.95-(O11/10))),480) | AS11: =IF((480*(10^(8.45-(O11/10))))<480,480*(10^(8.45-(O11/10))),480) | AT11: =IF((480*(10^(8.65-(O11/10))))<480,480*(10^(8.65-(O11/10))),480) | AU11: =IF(O11<80,"0",IF((P11-O11)<=2,('DPI art.191'!$G$3-(('DPI art.191'!$F$3-'DPI art.191'!$G$3)/4)*(P11-O11-2)),('DPI art.191'!$G$3-(('DPI art.191'!$F$3-'DPI art.191'!$H$3)/8)*(P11-O11-2)))) | AV11: =O11-AU11 | AW11: =IF(N11<135,N11,N11-'DPI art.191'!$I$3) | AX11: =IF(I11<80,"0",IF((J11-I11)<=2,('DPI art.191'!$G$7-(('DPI art.191'!$F$7-'DPI art.191'!$G$7)/4)*(I11-J11-2)),('DPI art.191'!$G$7-(('DPI art.191'!$G$7-'DPI art.191'!$H$7)/8)*(J11-I11-2)))) | AY11: =I11-AX11 | AZ11: =IF(H11<135,H11,H11-'DPI art.191'!$I$7) | BA11: =IF(O11<80,"0",IF((P11-O11)<=2,('DPI art.191'!$G$5-(('DPI art.191'!$F$5-'DPI art.191'!$G$5)/4)*(P11-O11-2)),('DPI art.191'!$G$5-(('DPI art.191'!$G$5-'DPI art.191'!$H$5)/8)*(P11-O11-2)))) | BB11: =R11-BA11 | BC11: =IF(N11<135,N11,N11-'DPI art.191'!$I$5) | BD11: =IF(O11<80,"0",IF((P11-O11)<=2,('DPI art.191'!$G$7-(('DPI art.191'!$F$7-'DPI art.191'!$G$7)/4)*(O11-P11-2)),('DPI art.191'!$G$7-(('DPI art.191'!$G$7-'DPI art.191'!$H$7)/8)*(P11-O11-2)))) | BE11: =O11-BD11 | BF11: =IF(N11<135,N11,N11-'DPI art.191'!$I$7) | BG11: =10^(0.1*R11) | BH11: =10^(0.1*X11) | BI11: =10^(0.1*AB11) | BJ11: =10^(0.1*AF11) | BK11: =10^(0.1*AJ11) | BL11: =10^(0.1*AN11) | BM11: =IF(R11>0,(O11-R11),"") | BN11: =IF(X11>0,(O11-X11),"") | BO11: =IF(AB11>0,(O11-AB11),"") | BP11: =IF(AF11>0,(O11-AF11),"") | BQ11: =IF(AJ11>0,(O11-AJ11),"") | BR11: =IF(AN11>0,(O11-AN11),"") | BS11: =COUNT(BM11:BR11) | BT11: =IF(BS11=0,0,IF(BS11=1,0,1/(BS11*(BS11-1)))) | BU11: =IF(R11>0,(BM11^2),"") | BV11: =IF(X11>0,(BN11^2),"") | BW11: =IF(AB11>0,(BO11^2),"") | BX11: =IF(AF11>0,(BP11^2),"") | BY11: =IF(AJ11>0,(BQ11^2),"") | BZ11: =IF(AN11>0,(BR11^2),"")
A12: 458/30 | B12: W7 | C12: Carrello elevatore | D12: KALMAR | E12: DCG160-12 | F12: Movimentazione con carrello elevatore | G12: 45996 | H12: Compito | I12: =IF((V12-R12)>3,"SI","") | J12: SI | M12: =IF(R12>0,(SQRT(BT12*(SUM(BU12:BZ12)))),"") | N12: =IF(T12>0,(MAX(T12,Z12,AD12,AH12,AL12,AP12))+SQRT(1.2^2+1^2),"") | O12: =IF(R12="",0,10*LOG10(SUM(BG12:BL12)/(COUNT(R12,X12,AB12,AF12,AJ12,AN12)))) | P12: =IF(AND(Y12="",AC12="",AG12="",AK12="",AO12=""),S12,AVERAGE(S12,Y12,AC12,AG12,AK12,AO12)+STDEV(S12,Y12,AC12,AG12,AK12,AO12)) | Q12: 300 | R12: 84.5 | S12: 94 | T12: 128 | W12: 300 | X12: 74.6 | Y12: 92.8 | Z12: 109.5 | AA12: 300 | AB12: 72.7 | AC12: 93.9 | AD12: 111.1 | AE12: 300 | AF12: 77 | AG12: 91.2 | AH12: 121.1 | AI12: 300 | AJ12: 83.3 | AK12: 92.1 | AL12: 117.1 | AM12: 300 | AN12: 72.2 | AO12: 87.8 | AP12: 116.4 | AQ12: =IF(AND((O12)<85,N12<137),"NO","SI") | AR12: =IF((480*(10^(7.95-(O12/10))))<480,480*(10^(7.95-(O12/10))),480) | AS12: =IF((480*(10^(8.45-(O12/10))))<480,480*(10^(8.45-(O12/10))),480) | AT12: =IF((480*(10^(8.65-(O12/10))))<480,480*(10^(8.65-(O12/10))),480) | AU12: =IF(O12<80,"0",IF((P12-O12)<=2,('DPI art.191'!$G$3-(('DPI art.191'!$F$3-'DPI art.191'!$G$3)/4)*(P12-O12-2)),('DPI art.191'!$G$3-(('DPI art.191'!$F$3-'DPI art.191'!$H$3)/8)*(P12-O12-2)))) | AV12: =O12-AU12 | AW12: =IF(N12<135,N12,N12-'DPI art.191'!$I$3) | AX12: =IF(I12<80,"0",IF((J12-I12)<=2,('DPI art.191'!$G$7-(('DPI art.191'!$F$7-'DPI art.191'!$G$7)/4)*(I12-J12-2)),('DPI art.191'!$G$7-(('DPI art.191'!$G$7-'DPI art.191'!$H$7)/8)*(J12-I12-2)))) | AY12: =I12-AX12 | AZ12: =IF(H12<135,H12,H12-'DPI art.191'!$I$7) | BA12: =IF(O12<80,"0",IF((P12-O12)<=2,('DPI art.191'!$G$5-(('DPI art.191'!$F$5-'DPI art.191'!$G$5)/4)*(P12-O12-2)),('DPI art.191'!$G$5-(('DPI art.191'!$G$5-'DPI art.191'!$H$5)/8)*(P12-O12-2)))) | BB12: =R12-BA12 | BC12: =IF(N12<135,N12,N12-'DPI art.191'!$I$5) | BD12: =IF(O12<80,"0",IF((P12-O12)<=2,('DPI art.191'!$G$7-(('DPI art.191'!$F$7-'DPI art.191'!$G$7)/4)*(O12-P12-2)),('DPI art.191'!$G$7-(('DPI art.191'!$G$7-'DPI art.191'!$H$7)/8)*(P12-O12-2)))) | BE12: =O12-BD12 | BF12: =IF(N12<135,N12,N12-'DPI art.191'!$I$7) | BG12: =10^(0.1*R12) | BH12: =10^(0.1*X12) | BI12: =10^(0.1*AB12) | BJ12: =10^(0.1*AF12) | BK12: =10^(0.1*AJ12) | BL12: =10^(0.1*AN12) | BM12: =IF(R12>0,(O12-R12),"") | BN12: =IF(X12>0,(O12-X12),"") | BO12: =IF(AB12>0,(O12-AB12),"") | BP12: =IF(AF12>0,(O12-AF12),"") | BQ12: =IF(AJ12>0,(O12-AJ12),"") | BR12: =IF(AN12>0,(O12-AN12),"") | BS12: =COUNT(BM12:BR12) | BT12: =IF(BS12=0,0,IF(BS12=1,0,1/(BS12*(BS12-1)))) | BU12: =IF(R12>0,(BM12^2),"") | BV12: =IF(X12>0,(BN12^2),"") | BW12: =IF(AB12>0,(BO12^2),"") | BX12: =IF(AF12>0,(BP12^2),"") | BY12: =IF(AJ12>0,(BQ12^2),"") | BZ12: =IF(AN12>0,(BR12^2),"")
A13: 458/27 | B13: W8 | C13: Carrello elevatore | D13: MANITOU | E13: MSI 50 T | F13: Movimentazione con carrello elevatore | G13: 45996 | H13: Compito | I13: =IF((V13-R13)>3,"SI","") | J13: SI | M13: =IF(R13>0,(SQRT(BT13*(SUM(BU13:BZ13)))),"") | N13: =IF(T13>0,(MAX(T13,Z13,AD13,AH13,AL13,AP13))+SQRT(1.2^2+1^2),"") | O13: =IF(R13="",0,10*LOG10(SUM(BG13:BL13)/(COUNT(R13,X13,AB13,AF13,AJ13,AN13)))) | P13: =IF(AND(Y13="",AC13="",AG13="",AK13="",AO13=""),S13,AVERAGE(S13,Y13,AC13,AG13,AK13,AO13)+STDEV(S13,Y13,AC13,AG13,AK13,AO13)) | Q13: 300 | R13: 83 | S13: 98.3 | T13: 115.1 | W13: 300 | X13: 88 | Y13: 100.3 | Z13: 118.6 | AA13: 300 | AB13: 92.5 | AC13: 96.8 | AD13: 126.4 | AE13: 300 | AF13: 85.7 | AG13: 96.1 | AH13: 118.1 | AI13: 300 | AJ13: 88.3 | AK13: 96.9 | AL13: 116.9 | AM13: 300 | AN13: 85.6 | AO13: 98.8 | AP13: 119.2 | AQ13: =IF(AND((O13)<85,N13<137),"NO","SI") | AR13: =IF((480*(10^(7.95-(O13/10))))<480,480*(10^(7.95-(O13/10))),480) | AS13: =IF((480*(10^(8.45-(O13/10))))<480,480*(10^(8.45-(O13/10))),480) | AT13: =IF((480*(10^(8.65-(O13/10))))<480,480*(10^(8.65-(O13/10))),480) | AU13: =IF(O13<80,"0",IF((P13-O13)<=2,('DPI art.191'!$G$3-(('DPI art.191'!$F$3-'DPI art.191'!$G$3)/4)*(P13-O13-2)),('DPI art.191'!$G$3-(('DPI art.191'!$F$3-'DPI art.191'!$H$3)/8)*(P13-O13-2)))) | AV13: =O13-AU13 | AW13: =IF(N13<135,N13,N13-'DPI art.191'!$I$3) | AX13: =IF(I13<80,"0",IF((J13-I13)<=2,('DPI art.191'!$G$7-(('DPI art.191'!$F$7-'DPI art.191'!$G$7)/4)*(I13-J13-2)),('DPI art.191'!$G$7-(('DPI art.191'!$G$7-'DPI art.191'!$H$7)/8)*(J13-I13-2)))) | AY13: =I13-AX13 | AZ13: =IF(H13<135,H13,H13-'DPI art.191'!$I$7) | BA13: =IF(O13<80,"0",IF((P13-O13)<=2,('DPI art.191'!$G$5-(('DPI art.191'!$F$5-'DPI art.191'!$G$5)/4)*(P13-O13-2)),('DPI art.191'!$G$5-(('DPI art.191'!$G$5-'DPI art.191'!$H$5)/8)*(P13-O13-2)))) | BB13: =R13-BA13 | BC13: =IF(N13<135,N13,N13-'DPI art.191'!$I$5) | BD13: =IF(O13<80,"0",IF((P13-O13)<=2,('DPI art.191'!$G$7-(('DPI art.191'!$F$7-'DPI art.191'!$G$7)/4)*(O13-P13-2)),('DPI art.191'!$G$7-(('DPI art.191'!$G$7-'DPI art.191'!$H$7)/8)*(P13-O13-2)))) | BE13: =O13-BD13 | BF13: =IF(N13<135,N13,N13-'DPI art.191'!$I$7) | BG13: =10^(0.1*R13) | BH13: =10^(0.1*X13) | BI13: =10^(0.1*AB13) | BJ13: =10^(0.1*AF13) | BK13: =10^(0.1*AJ13) | BL13: =10^(0.1*AN13) | BM13: =IF(R13>0,(O13-R13),"") | BN13: =IF(X13>0,(O13-X13),"") | BO13: =IF(AB13>0,(O13-AB13),"") | BP13: =IF(AF13>0,(O13-AF13),"") | BQ13: =IF(AJ13>0,(O13-AJ13),"") | BR13: =IF(AN13>0,(O13-AN13),"") | BS13: =COUNT(BM13:BR13) | BT13: =IF(BS13=0,0,IF(BS13=1,0,1/(BS13*(BS13-1)))) | BU13: =IF(R13>0,(BM13^2),"") | BV13: =IF(X13>0,(BN13^2),"") | BW13: =IF(AB13>0,(BO13^2),"") | BX13: =IF(AF13>0,(BP13^2),"") | BY13: =IF(AJ13>0,(BQ13^2),"") | BZ13: =IF(AN13>0,(BR13^2),"")
A14: 031/28 | B14: W9 | C14: Autogru | D14: LOCATELLI | E14: GRIL 8600 T | F14: Movimentazione con autogru in esterno | G14: 45996 | H14: Compito | I14: =IF((V14-R14)>3,"SI","") | J14: SI | M14: =IF(R14>0,(SQRT(BT14*(SUM(BU14:BZ14)))),"") | N14: =IF(T14>0,(MAX(T14,Z14,AD14,AH14,AL14,AP14))+SQRT(1.2^2+1^2),"") | O14: =IF(R14="",0,10*LOG10(SUM(BG14:BL14)/(COUNT(R14,X14,AB14,AF14,AJ14,AN14)))) | P14: =IF(AND(Y14="",AC14="",AG14="",AK14="",AO14=""),S14,AVERAGE(S14,Y14,AC14,AG14,AK14,AO14)+STDEV(S14,Y14,AC14,AG14,AK14,AO14)) | Q14: 300 | R14: 75.5 | S14: 89.1 | T14: 117 | W14: 300 | X14: 79.4 | Y14: 87.5 | Z14: 106 | AA14: 300 | AB14: 75.9 | AC14: 86.4 | AD14: 104 | AE14: 300 | AF14: 79.2 | AG14: 87.8 | AH14: 120.3 | AI14: 300 | AJ14: 81.2 | AK14: 90.3 | AL14: 117.4 | AM14: 300 | AN14: 80.9 | AO14: 92.8 | AP14: 114.5 | AQ14: =IF(AND((O14)<85,N14<137),"NO","SI") | AR14: =IF((480*(10^(7.95-(O14/10))))<480,480*(10^(7.95-(O14/10))),480) | AS14: =IF((480*(10^(8.45-(O14/10))))<480,480*(10^(8.45-(O14/10))),480) | AT14: =IF((480*(10^(8.65-(O14/10))))<480,480*(10^(8.65-(O14/10))),480) | AU14: =IF(O14<80,"0",IF((P14-O14)<=2,('DPI art.191'!$G$3-(('DPI art.191'!$F$3-'DPI art.191'!$G$3)/4)*(P14-O14-2)),('DPI art.191'!$G$3-(('DPI art.191'!$F$3-'DPI art.191'!$H$3)/8)*(P14-O14-2)))) | AV14: =O14-AU14 | AW14: =IF(N14<135,N14,N14-'DPI art.191'!$I$3) | AX14: =IF(I14<80,"0",IF((J14-I14)<=2,('DPI art.191'!$G$7-(('DPI art.191'!$F$7-'DPI art.191'!$G$7)/4)*(I14-J14-2)),('DPI art.191'!$G$7-(('DPI art.191'!$G$7-'DPI art.191'!$H$7)/8)*(J14-I14-2)))) | AY14: =I14-AX14 | AZ14: =IF(H14<135,H14,H14-'DPI art.191'!$I$7) | BA14: =IF(O14<80,"0",IF((P14-O14)<=2,('DPI art.191'!$G$5-(('DPI art.191'!$F$5-'DPI art.191'!$G$5)/4)*(P14-O14-2)),('DPI art.191'!$G$5-(('DPI art.191'!$G$5-'DPI art.191'!$H$5)/8)*(P14-O14-2)))) | BB14: =R14-BA14 | BC14: =IF(N14<135,N14,N14-'DPI art.191'!$I$5) | BD14: =IF(O14<80,"0",IF((P14-O14)<=2,('DPI art.191'!$G$7-(('DPI art.191'!$F$7-'DPI art.191'!$G$7)/4)*(O14-P14-2)),('DPI art.191'!$G$7-(('DPI art.191'!$G$7-'DPI art.191'!$H$7)/8)*(P14-O14-2)))) | BE14: =O14-BD14 | BF14: =IF(N14<135,N14,N14-'DPI art.191'!$I$7) | BG14: =10^(0.1*R14) | BH14: =10^(0.1*X14) | BI14: =10^(0.1*AB14) | BJ14: =10^(0.1*AF14) | BK14: =10^(0.1*AJ14) | BL14: =10^(0.1*AN14) | BM14: =IF(R14>0,(O14-R14),"") | BN14: =IF(X14>0,(O14-X14),"") | BO14: =IF(AB14>0,(O14-AB14),"") | BP14: =IF(AF14>0,(O14-AF14),"") | BQ14: =IF(AJ14>0,(O14-AJ14),"") | BR14: =IF(AN14>0,(O14-AN14),"") | BS14: =COUNT(BM14:BR14) | BT14: =IF(BS14=0,0,IF(BS14=1,0,1/(BS14*(BS14-1)))) | BU14: =IF(R14>0,(BM14^2),"") | BV14: =IF(X14>0,(BN14^2),"") | BW14: =IF(AB14>0,(BO14^2),"") | BX14: =IF(AF14>0,(BP14^2),"") | BY14: =IF(AJ14>0,(BQ14^2),"") | BZ14: =IF(AN14>0,(BR14^2),"")
A15: 031/33 | B15: W10 | C15: Autogru | D15: CAMS | E15: SP180 | F15: Movimentazione con autogru in esterno | G15: 45996 | H15: Compito | I15: =IF((V15-R15)>3,"SI","") | J15: SI | M15: =IF(R15>0,(SQRT(BT15*(SUM(BU15:BZ15)))),"") | N15: =IF(T15>0,(MAX(T15,Z15,AD15,AH15,AL15,AP15))+SQRT(1.2^2+1^2),"") | O15: =IF(R15="",0,10*LOG10(SUM(BG15:BL15)/(COUNT(R15,X15,AB15,AF15,AJ15,AN15)))) | P15: =IF(AND(Y15="",AC15="",AG15="",AK15="",AO15=""),S15,AVERAGE(S15,Y15,AC15,AG15,AK15,AO15)+STDEV(S15,Y15,AC15,AG15,AK15,AO15)) | Q15: 300 | R15: 81.5 | S15: 104.6 | T15: 131.2 | W15: 300 | X15: 80.6 | Y15: 107.5 | Z15: 121.1 | AA15: 300 | AB15: 81.4 | AC15: 110.3 | AD15: 121.2 | AE15: 300 | AF15: 82.8 | AG15: 106.1 | AH15: 120.7 | AI15: 300 | AJ15: 83 | AK15: 103.3 | AL15: 113.9 | AM15: 300 | AN15: 83.5 | AO15: 104 | AP15: 118.8 | AQ15: =IF(AND((O15)<85,N15<137),"NO","SI") | AR15: =IF((480*(10^(7.95-(O15/10))))<480,480*(10^(7.95-(O15/10))),480) | AS15: =IF((480*(10^(8.45-(O15/10))))<480,480*(10^(8.45-(O15/10))),480) | AT15: =IF((480*(10^(8.65-(O15/10))))<480,480*(10^(8.65-(O15/10))),480) | AU15: =IF(O15<80,"0",IF((P15-O15)<=2,('DPI art.191'!$G$3-(('DPI art.191'!$F$3-'DPI art.191'!$G$3)/4)*(P15-O15-2)),('DPI art.191'!$G$3-(('DPI art.191'!$F$3-'DPI art.191'!$H$3)/8)*(P15-O15-2)))) | AV15: =O15-AU15 | AW15: =IF(N15<135,N15,N15-'DPI art.191'!$I$3) | AX15: =IF(I15<80,"0",IF((J15-I15)<=2,('DPI art.191'!$G$7-(('DPI art.191'!$F$7-'DPI art.191'!$G$7)/4)*(I15-J15-2)),('DPI art.191'!$G$7-(('DPI art.191'!$G$7-'DPI art.191'!$H$7)/8)*(J15-I15-2)))) | AY15: =I15-AX15 | AZ15: =IF(H15<135,H15,H15-'DPI art.191'!$I$7) | BA15: =IF(O15<80,"0",IF((P15-O15)<=2,('DPI art.191'!$G$5-(('DPI art.191'!$F$5-'DPI art.191'!$G$5)/4)*(P15-O15-2)),('DPI art.191'!$G$5-(('DPI art.191'!$G$5-'DPI art.191'!$H$5)/8)*(P15-O15-2)))) | BB15: =R15-BA15 | BC15: =IF(N15<135,N15,N15-'DPI art.191'!$I$5) | BD15: =IF(O15<80,"0",IF((P15-O15)<=2,('DPI art.191'!$G$7-(('DPI art.191'!$F$7-'DPI art.191'!$G$7)/4)*(O15-P15-2)),('DPI art.191'!$G$7-(('DPI art.191'!$G$7-'DPI art.191'!$H$7)/8)*(P15-O15-2)))) | BE15: =O15-BD15 | BF15: =IF(N15<135,N15,N15-'DPI art.191'!$I$7) | BG15: =10^(0.1*R15) | BH15: =10^(0.1*X15) | BI15: =10^(0.1*AB15) | BJ15: =10^(0.1*AF15) | BK15: =10^(0.1*AJ15) | BL15: =10^(0.1*AN15) | BM15: =IF(R15>0,(O15-R15),"") | BN15: =IF(X15>0,(O15-X15),"") | BO15: =IF(AB15>0,(O15-AB15),"") | BP15: =IF(AF15>0,(O15-AF15),"") | BQ15: =IF(AJ15>0,(O15-AJ15),"") | BR15: =IF(AN15>0,(O15-AN15),"") | BS15: =COUNT(BM15:BR15) | BT15: =IF(BS15=0,0,IF(BS15=1,0,1/(BS15*(BS15-1)))) | BU15: =IF(R15>0,(BM15^2),"") | BV15: =IF(X15>0,(BN15^2),"") | BW15: =IF(AB15>0,(BO15^2),"") | BX15: =IF(AF15>0,(BP15^2),"") | BY15: =IF(AJ15>0,(BQ15^2),"") | BZ15: =IF(AN15>0,(BR15^2),"")
A16: 045/25 | B16: W11 | C16: Trattore | D16: NEW-HOLLAND | E16: T6-120 | F16: Trasferimenti con trattore in esterno | G16: 45996 | H16: Compito | I16: =IF((V16-R16)>3,"SI","") | J16: SI | M16: =IF(R16>0,(SQRT(BT16*(SUM(BU16:BZ16)))),"") | N16: =IF(T16>0,(MAX(T16,Z16,AD16,AH16,AL16,AP16))+SQRT(1.2^2+1^2),"") | O16: =IF(R16="",0,10*LOG10(SUM(BG16:BL16)/(COUNT(R16,X16,AB16,AF16,AJ16,AN16)))) | P16: =IF(AND(Y16="",AC16="",AG16="",AK16="",AO16=""),S16,AVERAGE(S16,Y16,AC16,AG16,AK16,AO16)+STDEV(S16,Y16,AC16,AG16,AK16,AO16)) | Q16: 300 | R16: 82 | S16: 92.2 | T16: 132.5 | W16: 300 | X16: 89.7 | Y16: 100.1 | Z16: 134.7 | AA16: 300 | AB16: 91.4 | AC16: 93.3 | AD16: 117.9 | AE16: 300 | AF16: 82.8 | AG16: 94.7 | AH16: 135 | AI16: 300 | AJ16: 89.7 | AK16: 92 | AL16: 128.7 | AM16: 300 | AN16: 90.2 | AO16: 94.5 | AP16: 133.9 | AQ16: =IF(AND((O16)<85,N16<137),"NO","SI") | AR16: =IF((480*(10^(7.95-(O16/10))))<480,480*(10^(7.95-(O16/10))),480) | AS16: =IF((480*(10^(8.45-(O16/10))))<480,480*(10^(8.45-(O16/10))),480) | AT16: =IF((480*(10^(8.65-(O16/10))))<480,480*(10^(8.65-(O16/10))),480) | AU16: =IF(O16<80,"0",IF((P16-O16)<=2,('DPI art.191'!$G$3-(('DPI art.191'!$F$3-'DPI art.191'!$G$3)/4)*(P16-O16-2)),('DPI art.191'!$G$3-(('DPI art.191'!$F$3-'DPI art.191'!$H$3)/8)*(P16-O16-2)))) | AV16: =O16-AU16 | AW16: =IF(N16<135,N16,N16-'DPI art.191'!$I$3) | AX16: =IF(I16<80,"0",IF((J16-I16)<=2,('DPI art.191'!$G$7-(('DPI art.191'!$F$7-'DPI art.191'!$G$7)/4)*(I16-J16-2)),('DPI art.191'!$G$7-(('DPI art.191'!$G$7-'DPI art.191'!$H$7)/8)*(J16-I16-2)))) | AY16: =I16-AX16 | AZ16: =IF(H16<135,H16,H16-'DPI art.191'!$I$7) | BA16: =IF(O16<80,"0",IF((P16-O16)<=2,('DPI art.191'!$G$5-(('DPI art.191'!$F$5-'DPI art.191'!$G$5)/4)*(P16-O16-2)),('DPI art.191'!$G$5-(('DPI art.191'!$G$5-'DPI art.191'!$H$5)/8)*(P16-O16-2)))) | BB16: =R16-BA16 | BC16: =IF(N16<135,N16,N16-'DPI art.191'!$I$5) | BD16: =IF(O16<80,"0",IF((P16-O16)<=2,('DPI art.191'!$G$7-(('DPI art.191'!$F$7-'DPI art.191'!$G$7)/4)*(O16-P16-2)),('DPI art.191'!$G$7-(('DPI art.191'!$G$7-'DPI art.191'!$H$7)/8)*(P16-O16-2)))) | BE16: =O16-BD16 | BF16: =IF(N16<135,N16,N16-'DPI art.191'!$I$7) | BG16: =10^(0.1*R16) | BH16: =10^(0.1*X16) | BI16: =10^(0.1*AB16) | BJ16: =10^(0.1*AF16) | BK16: =10^(0.1*AJ16) | BL16: =10^(0.1*AN16) | BM16: =IF(R16>0,(O16-R16),"") | BN16: =IF(X16>0,(O16-X16),"") | BO16: =IF(AB16>0,(O16-AB16),"") | BP16: =IF(AF16>0,(O16-AF16),"") | BQ16: =IF(AJ16>0,(O16-AJ16),"") | BR16: =IF(AN16>0,(O16-AN16),"") | BS16: =COUNT(BM16:BR16) | BT16: =IF(BS16=0,0,IF(BS16=1,0,1/(BS16*(BS16-1)))) | BU16: =IF(R16>0,(BM16^2),"") | BV16: =IF(X16>0,(BN16^2),"") | BW16: =IF(AB16>0,(BO16^2),"") | BX16: =IF(AF16>0,(BP16^2),"") | BY16: =IF(AJ16>0,(BQ16^2),"") | BZ16: =IF(AN16>0,(BR16^2),"")
A17: Gualdo 2 | B17: W12 | C17: Mola grande | D17: Bosch | E17: gws 22-230 J | F17: Molatura con mola grande | G17: 46003 | H17: Compito | I17: =IF((V17-R17)>3,"SI","") | J17: SI | M17: =IF(R17>0,(SQRT(BT17*(SUM(BU17:BZ17)))),"") | N17: =IF(T17>0,(MAX(T17,Z17,AD17,AH17,AL17,AP17))+SQRT(1.2^2+1^2),"") | O17: =IF(R17="",0,10*LOG10(SUM(BG17:BL17)/(COUNT(R17,X17,AB17,AF17,AJ17,AN17)))) | P17: =IF(AND(Y17="",AC17="",AG17="",AK17="",AO17=""),S17,AVERAGE(S17,Y17,AC17,AG17,AK17,AO17)+STDEV(S17,Y17,AC17,AG17,AK17,AO17)) | Q17: 300 | R17: 100.4 | S17: 99.9 | T17: 123.6 | W17: 300 | X17: 100.4 | Y17: 99.7 | Z17: 121 | AA17: 300 | AB17: 95 | AC17: 94.3 | AD17: 119.1 | AE17: 300 | AF17: 93.3 | AG17: 92.4 | AH17: 121 | AI17: 300 | AJ17: 99.9 | AK17: 98.9 | AL17: 120.6 | AM17: 300 | AN17: 98.6 | AO17: 98 | AP17: 121.8 | AQ17: =IF(AND((O17)<85,N17<137),"NO","SI") | AR17: =IF((480*(10^(7.95-(O17/10))))<480,480*(10^(7.95-(O17/10))),480) | AS17: =IF((480*(10^(8.45-(O17/10))))<480,480*(10^(8.45-(O17/10))),480) | AT17: =IF((480*(10^(8.65-(O17/10))))<480,480*(10^(8.65-(O17/10))),480) | AU17: =IF(O17<80,"0",IF((P17-O17)<=2,('DPI art.191'!$G$3-(('DPI art.191'!$F$3-'DPI art.191'!$G$3)/4)*(P17-O17-2)),('DPI art.191'!$G$3-(('DPI art.191'!$F$3-'DPI art.191'!$H$3)/8)*(P17-O17-2)))) | AV17: =O17-AU17 | AW17: =IF(N17<135,N17,N17-'DPI art.191'!$I$3) | AX17: =IF(I17<80,"0",IF((J17-I17)<=2,('DPI art.191'!$G$7-(('DPI art.191'!$F$7-'DPI art.191'!$G$7)/4)*(I17-J17-2)),('DPI art.191'!$G$7-(('DPI art.191'!$G$7-'DPI art.191'!$H$7)/8)*(J17-I17-2)))) | AY17: =I17-AX17 | AZ17: =IF(H17<135,H17,H17-'DPI art.191'!$I$7) | BA17: =IF(O17<80,"0",IF((P17-O17)<=2,('DPI art.191'!$G$5-(('DPI art.191'!$F$5-'DPI art.191'!$G$5)/4)*(P17-O17-2)),('DPI art.191'!$G$5-(('DPI art.191'!$G$5-'DPI art.191'!$H$5)/8)*(P17-O17-2)))) | BB17: =R17-BA17 | BC17: =IF(N17<135,N17,N17-'DPI art.191'!$I$5) | BD17: =IF(O17<80,"0",IF((P17-O17)<=2,('DPI art.191'!$G$7-(('DPI art.191'!$F$7-'DPI art.191'!$G$7)/4)*(O17-P17-2)),('DPI art.191'!$G$7-(('DPI art.191'!$G$7-'DPI art.191'!$H$7)/8)*(P17-O17-2)))) | BE17: =O17-BD17 | BF17: =IF(N17<135,N17,N17-'DPI art.191'!$I$7) | BG17: =10^(0.1*R17) | BH17: =10^(0.1*X17) | BI17: =10^(0.1*AB17) | BJ17: =10^(0.1*AF17) | BK17: =10^(0.1*AJ17) | BL17: =10^(0.1*AN17) | BM17: =IF(R17>0,(O17-R17),"") | BN17: =IF(X17>0,(O17-X17),"") | BO17: =IF(AB17>0,(O17-AB17),"") | BP17: =IF(AF17>0,(O17-AF17),"") | BQ17: =IF(AJ17>0,(O17-AJ17),"") | BR17: =IF(AN17>0,(O17-AN17),"") | BS17: =COUNT(BM17:BR17) | BT17: =IF(BS17=0,0,IF(BS17=1,0,1/(BS17*(BS17-1)))) | BU17: =IF(R17>0,(BM17^2),"") | BV17: =IF(X17>0,(BN17^2),"") | BW17: =IF(AB17>0,(BO17^2),"") | BX17: =IF(AF17>0,(BP17^2),"") | BY17: =IF(AJ17>0,(BQ17^2),"") | BZ17: =IF(AN17>0,(BR17^2),"")
... A25: Verniciatura | B25: W20 | C25: Verniciatura | D25: / | E25: / | F25: Vernciciatura | G25: 46003 | H25: Compito | I25: =IF((V25-R25)>3,"SI","") | J25: SI | M25: =IF(R25>0,(SQRT(BT25*(SUM(BU25:BZ25)))),"") | N25: =IF(T25>0,(MAX(T25,Z25,AD25,AH25,AL25,AP25))+SQRT(1.2^2+1^2),"") | O25: =IF(R25="",0,10*LOG10(SUM(BG25:BL25)/(COUNT(R25,X25,AB25,AF25,AJ25,AN25)))) | P25: =IF(AND(Y25="",AC25="",AG25="",AK25="",AO25=""),S25,AVERAGE(S25,Y25,AC25,AG25,AK25,AO25)+STDEV(S25,Y25,AC25,AG25,AK25,AO25)) | Q25: 300 | R25: 81.4 | S25: 84 | T25: 116.1 | W25: 300 | X25: 81.9 | Y25: 83.7 | Z25: 119.5 | AA25: 300 | AB25: 80.5 | AC25: 83.1 | AD25: 121.1 | AE25: 300 | AF25: 74 | AG25: 75.2 | AH25: 111.6 | AI25: 300 | AJ25: 78 | AK25: 78.7 | AL25: 114.8 | AM25: 300 | AN25: 79.4 | AO25: 81.4 | AP25: 116.8 | AQ25: =IF(AND((O25)<85,N25<137),"NO","SI") | AR25: =IF((480*(10^(7.95-(O25/10))))<480,480*(10^(7.95-(O25/10))),480) | AS25: =IF((480*(10^(8.45-(O25/10))))<480,480*(10^(8.45-(O25/10))),480) | AT25: =IF((480*(10^(8.65-(O25/10))))<480,480*(10^(8.65-(O25/10))),480) | AU25: =IF(O25<80,"0",IF((P25-O25)<=2,('DPI art.191'!$G$3-(('DPI art.191'!$F$3-'DPI art.191'!$G$3)/4)*(P25-O25-2)),('DPI art.191'!$G$3-(('DPI art.191'!$F$3-'DPI art.191'!$H$3)/8)*(P25-O25-2)))) | AV25: =O25-AU25 | AW25: =IF(N25<135,N25,N25-'DPI art.191'!$I$3) | AX25: =IF(I25<80,"0",IF((J25-I25)<=2,('DPI art.191'!$G$7-(('DPI art.191'!$F$7-'DPI art.191'!$G$7)/4)*(I25-J25-2)),('DPI art.191'!$G$7-(('DPI art.191'!$G$7-'DPI art.191'!$H$7)/8)*(J25-I25-2)))) | AY25: =I25-AX25 | AZ25: =IF(H25<135,H25,H25-'DPI art.191'!$I$7) | BA25: =IF(O25<80,"0",IF((P25-O25)<=2,('DPI art.191'!$G$5-(('DPI art.191'!$F$5-'DPI art.191'!$G$5)/4)*(P25-O25-2)),('DPI art.191'!$G$5-(('DPI art.191'!$G$5-'DPI art.191'!$H$5)/8)*(P25-O25-2)))) | BB25: =R25-BA25 | BC25: =IF(N25<135,N25,N25-'DPI art.191'!$I$5) | BD25: =IF(O25<80,"0",IF((P25-O25)<=2,('DPI art.191'!$G$7-(('DPI art.191'!$F$7-'DPI art.191'!$G$7)/4)*(O25-P25-2)),('DPI art.191'!$G$7-(('DPI art.191'!$G$7-'DPI art.191'!$H$7)/8)*(P25-O25-2)))) | BE25: =O25-BD25 | BF25: =IF(N25<135,N25,N25-'DPI art.191'!$I$7) | BG25: =10^(0.1*R25) | BH25: =10^(0.1*X25) | BI25: =10^(0.1*AB25) | BJ25: =10^(0.1*AF25) | BK25: =10^(0.1*AJ25) | BL25: =10^(0.1*AN25) | BM25: =IF(R25>0,(O25-R25),"") | BN25: =IF(X25>0,(O25-X25),"") | BO25: =IF(AB25>0,(O25-AB25),"") | BP25: =IF(AF25>0,(O25-AF25),"") | BQ25: =IF(AJ25>0,(O25-AJ25),"") | BR25: =IF(AN25>0,(O25-AN25),"") | BS25: =COUNT(BM25:BR25) | BT25: =IF(BS25=0,0,IF(BS25=1,0,1/(BS25*(BS25-1)))) | BU25: =IF(R25>0,(BM25^2),"") | BV25: =IF(X25>0,(BN25^2),"") | BW25: =IF(AB25>0,(BO25^2),"") | BX25: =IF(AF25>0,(BP25^2),"") | BY25: =IF(AJ25>0,(BQ25^2),"") | BZ25: =IF(AN25>0,(BR25^2),"")
A26: 273/11 | B26: D1 | C26: Sega a nastro | D26: FMB | E26: OLIMPUS 2 - Ø 500mm | F26: Taglio con sega a nastro | G26: 45996 | H26: Compito | I26: =IF((V26-R26)>3,"SI","") | J26: =IF((U26-R26)>3,"SI","") | M26: =IF(R26>0,(SQRT(BT26*(SUM(BU26:BZ26)))),"") | N26: =IF(T26>0,(MAX(T26,Z26,AD26,AH26,AL26,AP26))+SQRT(1.2^2+1^2),"") | O26: =IF(R26="",0,10*LOG10(SUM(BG26:BL26)/(COUNT(R26,X26,AB26,AF26,AJ26,AN26)))) | P26: =IF(AND(Y26="",AC26="",AG26="",AK26="",AO26=""),S26,AVERAGE(S26,Y26,AC26,AG26,AK26,AO26)+STDEV(S26,Y26,AC26,AG26,AK26,AO26)) | Q26: 300 | R26: 91.9 | S26: 91.2 | T26: 107.6 | U26: 92 | V26: 95.1 | W26: 300 | X26: 81.8 | Y26: 81.9 | Z26: 99.5 | AA26: 300 | AB26: 85.3 | AC26: 85 | AD26: 102.5 | AE26: 300 | AF26: 86.4 | AG26: 86 | AH26: 102.4 | AI26: 300 | AJ26: 85.7 | AK26: 85.4 | AL26: 103.1 | AM26: 300 | AN26: 83.6 | AO26: 83.3 | AP26: 104.6 | AQ26: =IF(AND((O26)<85,N26<137),"NO","SI") | AR26: =IF((480*(10^(7.95-(O26/10))))<480,480*(10^(7.95-(O26/10))),480) | AS26: =IF((480*(10^(8.45-(O26/10))))<480,480*(10^(8.45-(O26/10))),480) | AT26: =IF((480*(10^(8.65-(O26/10))))<480,480*(10^(8.65-(O26/10))),480) | AU26: =IF(O26<80,"0",IF((P26-O26)<=2,('DPI art.191'!$G$3-(('DPI art.191'!$F$3-'DPI art.191'!$G$3)/4)*(P26-O26-2)),('DPI art.191'!$G$3-(('DPI art.191'!$F$3-'DPI art.191'!$H$3)/8)*(P26-O26-2)))) | AV26: =O26-AU26 | AW26: =IF(N26<135,N26,N26-'DPI art.191'!$I$3) | AX26: =IF(I26<80,"0",IF((J26-I26)<=2,('DPI art.191'!$G$7-(('DPI art.191'!$F$7-'DPI art.191'!$G$7)/4)*(I26-J26-2)),('DPI art.191'!$G$7-(('DPI art.191'!$G$7-'DPI art.191'!$H$7)/8)*(J26-I26-2)))) | AY26: =I26-AX26 | AZ26: =IF(H26<135,H26,H26-'DPI art.191'!$I$7) | BA26: =IF(O26<80,"0",IF((P26-O26)<=2,('DPI art.191'!$G$5-(('DPI art.191'!$F$5-'DPI art.191'!$G$5)/4)*(P26-O26-2)),('DPI art.191'!$G$5-(('DPI art.191'!$G$5-'DPI art.191'!$H$5)/8)*(P26-O26-2)))) | BB26: =R26-BA26 | BC26: =IF(N26<135,N26,N26-'DPI art.191'!$I$5) | BD26: =IF(O26<80,"0",IF((P26-O26)<=2,('DPI art.191'!$G$7-(('DPI art.191'!$F$7-'DPI art.191'!$G$7)/4)*(O26-P26-2)),('DPI art.191'!$G$7-(('DPI art.191'!$G$7-'DPI art.191'!$H$7)/8)*(P26-O26-2)))) | BE26: =O26-BD26 | BF26: =IF(N26<135,N26,N26-'DPI art.191'!$I$7) | BG26: =10^(0.1*R26) | BH26: =10^(0.1*X26) | BI26: =10^(0.1*AB26) | BJ26: =10^(0.1*AF26) | BK26: =10^(0.1*AJ26) | BL26: =10^(0.1*AN26) | BM26: =IF(R26>0,(O26-R26),"") | BN26: =IF(X26>0,(O26-X26),"") | BO26: =IF(AB26>0,(O26-AB26),"") | BP26: =IF(AF26>0,(O26-AF26),"") | BQ26: =IF(AJ26>0,(O26-AJ26),"") | BR26: =IF(AN26>0,(O26-AN26),"") | BS26: =COUNT(BM26:BR26) | BT26: =IF(BS26=0,0,IF(BS26=1,0,1/(BS26*(BS26-1)))) | BU26: =IF(R26>0,(BM26^2),"") | BV26: =IF(X26>0,(BN26^2),"") | BW26: =IF(AB26>0,(BO26^2),"") | BX26: =IF(AF26>0,(BP26^2),"") | BY26: =IF(AJ26>0,(BQ26^2),"") | BZ26: =IF(AN26>0,(BR26^2),"")
A27: 273/12 | B27: D2 | C27: Sega a nastro | D27: SCORTEGAGNA | E27: RUSCH 260/320 AF | F27: Taglio con sega a nastro | G27: 45996 | H27: Compito | I27: =IF((V27-R27)>3,"SI","") | J27: =IF((U27-R27)>3,"SI","") | M27: =IF(R27>0,(SQRT(BT27*(SUM(BU27:BZ27)))),"") | N27: =IF(T27>0,(MAX(T27,Z27,AD27,AH27,AL27,AP27))+SQRT(1.2^2+1^2),"") | O27: =IF(R27="",0,10*LOG10(SUM(BG27:BL27)/(COUNT(R27,X27,AB27,AF27,AJ27,AN27)))) | P27: =IF(AND(Y27="",AC27="",AG27="",AK27="",AO27=""),S27,AVERAGE(S27,Y27,AC27,AG27,AK27,AO27)+STDEV(S27,Y27,AC27,AG27,AK27,AO27)) | Q27: 300 | R27: 76.5 | S27: 78.6 | T27: 105.9 | U27: 76.5 | V27: 79.9 | W27: 300 | X27: 74.8 | Y27: 77.9 | Z27: 106.8 | AA27: 300 | AB27: 78.2 | AC27: 79.2 | AD27: 102.2 | AE27: 300 | AF27: 77.8 | AG27: 79 | AH27: 102.7 | AI27: 300 | AJ27: 79.8 | AK27: 81 | AL27: 102 | AM27: 300 | AN27: 76.9 | AO27: 78.7 | AP27: 99.9 | AQ27: =IF(AND((O27)<85,N27<137),"NO","SI") | AR27: =IF((480*(10^(7.95-(O27/10))))<480,480*(10^(7.95-(O27/10))),480) | AS27: =IF((480*(10^(8.45-(O27/10))))<480,480*(10^(8.45-(O27/10))),480) | AT27: =IF((480*(10^(8.65-(O27/10))))<480,480*(10^(8.65-(O27/10))),480) | AU27: =IF(O27<80,"0",IF((P27-O27)<=2,('DPI art.191'!$G$3-(('DPI art.191'!$F$3-'DPI art.191'!$G$3)/4)*(P27-O27-2)),('DPI art.191'!$G$3-(('DPI art.191'!$F$3-'DPI art.191'!$H$3)/8)*(P27-O27-2)))) | AV27: =O27-AU27 | AW27: =IF(N27<135,N27,N27-'DPI art.191'!$I$3) | AX27: =IF(I27<80,"0",IF((J27-I27)<=2,('DPI art.191'!$G$7-(('DPI art.191'!$F$7-'DPI art.191'!$G$7)/4)*(I27-J27-2)),('DPI art.191'!$G$7-(('DPI art.191'!$G$7-'DPI art.191'!$H$7)/8)*(J27-I27-2)))) | AY27: =I27-AX27 | AZ27: =IF(H27<135,H27,H27-'DPI art.191'!$I$7) | BA27: =IF(O27<80,"0",IF((P27-O27)<=2,('DPI art.191'!$G$5-(('DPI art.191'!$F$5-'DPI art.191'!$G$5)/4)*(P27-O27-2)),('DPI art.191'!$G$5-(('DPI art.191'!$G$5-'DPI art.191'!$H$5)/8)*(P27-O27-2)))) | BB27: =R27-BA27 | BC27: =IF(N27<135,N27,N27-'DPI art.191'!$I$5) | BD27: =IF(O27<80,"0",IF((P27-O27)<=2,('DPI art.191'!$G$7-(('DPI art.191'!$F$7-'DPI art.191'!$G$7)/4)*(O27-P27-2)),('DPI art.191'!$G$7-(('DPI art.191'!$G$7-'DPI art.191'!$H$7)/8)*(P27-O27-2)))) | BE27: =O27-BD27 | BF27: =IF(N27<135,N27,N27-'DPI art.191'!$I$7) | BG27: =10^(0.1*R27) | BH27: =10^(0.1*X27) | BI27: =10^(0.1*AB27) | BJ27: =10^(0.1*AF27) | BK27: =10^(0.1*AJ27) | BL27: =10^(0.1*AN27) | BM27: =IF(R27>0,(O27-R27),"") | BN27: =IF(X27>0,(O27-X27),"") | BO27: =IF(AB27>0,(O27-AB27),"") | BP27: =IF(AF27>0,(O27-AF27),"") | BQ27: =IF(AJ27>0,(O27-AJ27),"") | BR27: =IF(AN27>0,(O27-AN27),"") | BS27: =COUNT(BM27:BR27) | BT27: =IF(BS27=0,0,IF(BS27=1,0,1/(BS27*(BS27-1)))) | BU27: =IF(R27>0,(BM27^2),"") | BV27: =IF(X27>0,(BN27^2),"") | BW27: =IF(AB27>0,(BO27^2),"") | BX27: =IF(AF27>0,(BP27^2),"") | BY27: =IF(AJ27>0,(BQ27^2),"") | BZ27: =IF(AN27>0,(BR27^2),"")
